Workbook
Name Nav_DealAssumptions: 'UW Model'!$C$5
Name Nav_Expenses: 'UW Model'!$C$76
Name Nav_GrowthRates: 'UW Model'!$C$102
Name Nav_Income: 'UW Model'!$C$46
Name Nav_QuikUw: 'UW Model'!$T$6
Name Nav_Summary: #REF!
Name Nav_UnitMix: 'UW Model'!$C$26
Name RentGraphInPlaceRent: INDIRECT(#REF!)
Name RentGraphLabels: INDIRECT(#REF!)
Name RentGraphMarket: INDIRECT(#REF!)
Name RentGraphMarketRentAdd: INDIRECT(#REF!)
Name RentGraphReno: INDIRECT(#REF!)
Name RentGraphRenoUnits: INDIRECT(#REF!)
Name RentGraphTotal: INDIRECT(#REF!)
Name RentGraphTotalUnits: INDIRECT(#REF!)
Name ROIAbove: INDIRECT(#REF!)
Name ROIBelow: INDIRECT(#REF!)
Name ROIGoal: INDIRECT(#REF!)
Name T12_Flow: #REF!
Name T12Data: #REF!
Name UnitMixLabels: INDIRECT(#REF!)
Name UnitMixValues: INDIRECT(#REF!)
Name UW_Baths: 'UW Model'!$F$28:$F$42
Name UW_Beds: 'UW Model'!$E$28:$E$42
Name UW_InPlaceRent: 'UW Model'!$I$28:$I$42
Name UW_MarketRent: 'UW Model'!$L$28:$L$42
Name UW_SF: 'UW Model'!$G$28:$G$42
Name UW_UnitNames: 'UW Model'!$C$28:$C$42
Name UW_Units: 'UW Model'!$H$28:$H$42

Sheet Disclaimer
N1: ="Version "&MAX(Version!B2:B1000) -> Version 1.01
E3: Disclaimer: This spreadsheet is for your personal use only. You may use and access this spreadsheet on multiple devices but you may not share it with other users. All of the information contained herein is believed to be true and accurate. The author shall not be held liable to you for any damages arising from the use or the inability to use this software
B12: Compatibility | C12: Excel 2021, Excel 2021 for Mac ONLY (Not Excel for web, older versions of Excel, or Google sheets)
B15: Font Color Ledged | C15: BLUE | D15: Input / Manual entry
C16: ORANGE | D16: Formulas, but can be overwritten
C17: BLACK | D17: Formulas - do not change
B24: Copyright © MFA 2022 - MFAUnderwriting.com

Sheet UW Process
C2: UNDERWRITING STEPS & DATA INPUT CHECK
C3: STEP | D3: UNDERWRITING TASKS (link to tab) | E3: VIDEO TUTORIALS | F3: INPUT CHECK | AH3: Required | AI3: Completed | AJ3: Indicator | AK3: Section Indicator
A4: =AJ4 -> 0 | C4: Step 1 | D4: Input Deal Assumptions | E4: Deal Assumptions | F4: =IF(AJ4=1,"✅ "&AG4,"⬜ "&AG4) -> ⬜ Property Info | AF4: Deal Assumptions | AG4: Property Info | AH4: 4 | AI4: =COUNTA('UW Model'!E7:G7,'UW Model'!E8:G8,'UW Model'!E9,'UW Model'!G9) -> 1 | AJ4: =IF(AI4=AH4,1,0) -> 0 | AK4: =IF(SUM(AJ4:AJ10)=7,1,0) -> 0
A5: =AJ5 -> 0 | F5: =IF(AJ5=1,"✅ "&AG5,"⬜ "&AG5) -> ⬜ Purchase Assumptions | AG5: Purchase Assumptions | AH5: 7 | AI5: =COUNTA('UW Model'!G11:G14,'UW Model'!G16:G18) -> 5 | AJ5: =IF(AI5=AH5,1,0) -> 0
A6: =AJ6 -> 1 | F6: =IF(AJ6=1,"✅ "&AG6,"⬜ "&AG6) -> ✅ Exit Assumptions | AG6: Exit Assumptions | AH6: 4 | AI6: =COUNTA('UW Model'!G20:G22,'UW Model'!F23) -> 4 | AJ6: =IF(AI6=AH6,1,0) -> 1
A7: =AJ7 -> 0 | F7: =IF(AJ7=1,"✅ "&AG7,"⬜ "&AG7) -> ⬜ Debt Structure | AG7: Debt Structure | AH7: 1 | AI7: =IF('UW Model'!K8>0,1,0) -> 0 | AJ7: =IF(AI7=AH7,1,0) -> 0
A8: =AJ8 -> 1 | F8: =IF(AJ8=1,"✅ "&AG8,"⬜ "&AG8) -> ✅ Deal Structure | AG8: Deal Structure | AH8: 6 | AI8: =COUNTA('UW Model'!O7:O12) -> 6 | AJ8: =IF(AI8=AH8,1,0) -> 1
A9: =AJ9 -> 0 | F9: =IF(AJ9=1,"✅ "&AG9,"⬜ "&AG9) -> ⬜ Renovation Assumptions | AG9: Renovation Assumptions | AH9: 1 | AI9: =IF(AND('UW Model'!O15>'UW Model'!O14,'UW Model'!O23>0),1,0) -> 0 | AJ9: =IF(AI9=AH9,1,0) -> 0
A10: =AJ10 -> 1 | F10: =IF(AJ10=1,"✅ "&AG10,"⬜ "&AG10) -> ✅ KPIs | AG10: KPIs | AH10: 4 | AI10: =COUNTA('UW Model'!R7:R10) -> 4 | AJ10: =IF(AI10=AH10,1,0) -> 1
A11: =AJ11 -> 0 | C11: Step 2 | D11: Unit Mix, Rents, Interior Renovation Strategy | E11: Unit Mix, Rent, & Interior Renovation | F11: =IF(AJ11=1,"✅ "&AG11,"⬜ "&AG11) -> ⬜ Bed | AF11: Unit Mix Table | AG11: Bed | AH11: 1 | AI11: =IF(COUNTA(UW_Beds)>0,1,0) -> 0 | AJ11: =IF(AI11=AH11,1,0) -> 0 | AK11: =IF(SUM(AJ11:AJ17)=7,1,0) -> 0
A12: =AJ12 -> 0 | F12: =IF(AJ12=1,"✅ "&AG12,"⬜ "&AG12) -> ⬜ Bath | AG12: Bath | AH12: 1 | AI12: =IF(COUNTA(UW_Baths)>0,1,0) -> 0 | AJ12: =IF(AI12=AH12,1,0) -> 0
A13: =AJ13 -> 0 | F13: =IF(AJ13=1,"✅ "&AG13,"⬜ "&AG13) -> ⬜ Sqft | AG13: Sqft | AH13: 1 | AI13: =IF(COUNTA(UW_SF)>0,1,0) -> 0 | AJ13: =IF(AI13=AH13,1,0) -> 0
A14: =AJ14 -> 0 | F14: =IF(AJ14=1,"✅ "&AG14,"⬜ "&AG14) -> ⬜ Units | AG14: Units | AH14: 1 | AI14: =IF(COUNTA(UW_Units)>0,1,0) -> 0 | AJ14: =IF(AI14=AH14,1,0) -> 0
A15: =AJ15 -> 0 | F15: =IF(AJ15=1,"✅ "&AG15,"⬜ "&AG15) -> ⬜ In-Place Rents | AG15: In-Place Rents | AH15: 1 | AI15: =IF(COUNTA(UW_InPlaceRent)>0,1,0) -> 0 | AJ15: =IF(AI15=AH15,1,0) -> 0
A16: =AJ16 -> 0 | F16: =IF(AJ16=1,"✅ "&AG16,"⬜ "&AG16) -> ⬜ Market Rents | AG16: Market Rents | AH16: 1 | AI16: =IF(COUNTA(UW_MarketRent)>0,1,0) -> 0 | AJ16: =IF(AI16=AH16,1,0) -> 0
A17: =AJ17 -> 0 | F17: =IF(AJ17=1,"✅ "&AG17,"⬜ "&AG17) -> ⬜ Interior Renovations | AG17: Interior Renovations | AH17: 1 | AI17: =IF(AND('UW Model'!O43>0,'UW Model'!P43>0,'UW Model'!R43>0),1,0) -> 0 | AJ17: =IF(AI17=AH17,1,0) -> 0
A18: =AJ18 -> 0 | C18: Step 3 | D18: Income | E18: Income, Expenses, & Growth | F18: =IF(AJ18=1,"✅ "&AG18,"⬜ "&AG18) -> ⬜ GPR | AF18: Income | AG18: GPR | AH18: 1 | AI18: =IF('UW Model'!M48>0,1,0) -> 0 | AJ18: =IF(AI18=AH18,1,0) -> 0 | AK18: =IF(SUM(AJ18:AJ21)=4,1,0) -> 0
A19: =AJ19 -> 0 | F19: =IF(AJ19=1,"✅ "&AG19,"⬜ "&AG19) -> ⬜ Income Detractors | AG19: Income Detractors | AH19: 1 | AI19: =IF(SUM('UW Model'!K56:K60)>0,1,0) -> 0 | AJ19: =IF(AI19=AH19,1,0) -> 0
A20: =AJ20 -> 0 | F20: =IF(AJ20=1,"✅ "&AG20,"⬜ "&AG20) -> ⬜ RUBS | AG20: RUBS | AH20: 1 | AI20: =IF('UW Model'!M64>0,1,0) -> 0 | AJ20: =IF(AI20=AH20,1,0) -> 0
A21: =AJ21 -> 0 | F21: =IF(AJ21=1,"✅ "&AG21,"⬜ "&AG21) -> ⬜ Other Income | AG21: Other Income | AH21: 1 | AI21: =IF('UW Model'!M65>0,1,0) -> 0 | AJ21: =IF(AI21=AH21,1,0) -> 0
A22: =AJ22 -> 0 | C22: Step 4 | D22: Expenses | E22: Income, Expenses, & Growth | F22: =IF(AJ22=1,"✅ "&AG22,"⬜ "&AG22) -> ⬜ Payroll | AF22: Expenses | AG22: Payroll | AH22: 1 | AI22: =IF('UW Model'!M78>1,1,0) -> 0 | AJ22: =IF(AI22=AH22,1,0) -> 0 | AK22: =IF(SUM(AJ22:AJ31)=10,1,0) -> 0
A23: =AJ23 -> 0 | F23: =IF(AJ23=1,"✅ "&AG23,"⬜ "&AG23) -> ⬜ Advertising & Marketing | AG23: Advertising & Marketing | AH23: 1 | AI23: =IF('UW Model'!M79>1,1,0) -> 0 | AJ23: =IF(AI23=AH23,1,0) -> 0
A24: =AJ24 -> 0 | F24: =IF(AJ24=1,"✅ "&AG24,"⬜ "&AG24) -> ⬜ General & Administrative | AG24: General & Administrative | AH24: 1 | AI24: =IF('UW Model'!M80>1,1,0) -> 0 | AJ24: =IF(AI24=AH24,1,0) -> 0 | AL24: Used for UW Aid Conditional Formatting
A25: =AJ25 -> 0 | F25: =IF(AJ25=1,"✅ "&AG25,"⬜ "&AG25) -> ⬜ Utilities | AG25: Utilities | AH25: 1 | AI25: =IF('UW Model'!M81>1,1,0) -> 0 | AJ25: =IF(AI25=AH25,1,0) -> 0 | AN25: T-12 Mapped | AP25: =IF(AND(#REF!>0,#REF!>0),TRUE,FALSE) -> #REF!
A26: =AJ26 -> 0 | F26: =IF(AJ26=1,"✅ "&AG26,"⬜ "&AG26) -> ⬜ Repairs & Maintenance | AG26: Repairs & Maintenance | AH26: 1 | AI26: =IF('UW Model'!M82>1,1,0) -> 0 | AJ26: =IF(AI26=AH26,1,0) -> 0
A27: =AJ27 -> 0 | F27: =IF(AJ27=1,"✅ "&AG27,"⬜ "&AG27) -> ⬜ Contract Services | AG27: Contract Services | AH27: 1 | AI27: =IF('UW Model'!M83>1,1,0) -> 0 | AJ27: =IF(AI27=AH27,1,0) -> 0
A28: =AJ28 -> 0 | F28: =IF(AJ28=1,"✅ "&AG28,"⬜ "&AG28) -> ⬜ Management Fee | AG28: Management Fee | AH28: 1 | AI28: =IF('UW Model'!M84>1,1,0) -> 0 | AJ28: =IF(AI28=AH28,1,0) -> 0
A29: =AJ29 -> 0 | F29: =IF(AJ29=1,"✅ "&AG29,"⬜ "&AG29) -> ⬜ Make Ready | AG29: Make Ready | AH29: 1 | AI29: =IF('UW Model'!M85>1,1,0) -> 0 | AJ29: =IF(AI29=AH29,1,0) -> 0
A30: =AJ30 -> 0 | F30: =IF(AJ30=1,"✅ "&AG30,"⬜ "&AG30) -> ⬜ Taxes | AG30: Taxes | AH30: 1 | AI30: =IF('UW Model'!M86>1,1,0) -> 0 | AJ30: =IF(AI30=AH30,1,0) -> 0
A31: =AJ31 -> 0 | F31: =IF(AJ31=1,"✅ "&AG31,"⬜ "&AG31) -> ⬜ Insurance | AG31: Insurance | AH31: 1 | AI31: =IF('UW Model'!M87>1,1,0) -> 0 | AJ31: =IF(AI31=AH31,1,0) -> 0
A32: =AJ32 -> 1 | C32: Step 5 | D32: Growth Rates & % GPR Assumptions | E32: Income, Expenses, & Growth | F32: =IF(AJ32=1,"✅ "&AG32,"⬜ "&AG32) -> ✅ Rent | AF32: Growth Rate | AG32: Rent | AH32: 1 | AI32: =IF(SUM('UW Model'!M104:Q104)>0,1,0) -> 1 | AJ32: =IF(AI32=AH32,1,0) -> 1 | AK32: =IF(SUM(AJ32:AJ37)=6,1,0) -> 1
A33: =AJ33 -> 1 | F33: =IF(AJ33=1,"✅ "&AG33,"⬜ "&AG33) -> ✅ Other Income | AG33: Other Income | AH33: 1 | AI33: =IF(SUM('UW Model'!N112:Q112)>0,1,0) -> 1 | AJ33: =IF(AI33=AH33,1,0) -> 1
A34: =AJ34 -> 1 | F34: =IF(AJ34=1,"✅ "&AG34,"⬜ "&AG34) -> ✅ Vacancy | AG34: Vacancy | AH34: 1 | AI34: =IF(SUM('UW Model'!N107:Q107)>0,1,0) -> 1 | AJ34: =IF(AI34=AH34,1,0) -> 1
A35: =AJ35 -> 1 | F35: =IF(AJ35=1,"✅ "&AG35,"⬜ "&AG35) -> ✅ % GPR | AG35: % GPR | AH35: 1 | AI35: =IF(SUM('UW Model'!N108:Q110)>0,1,0) -> 1 | AJ35: =IF(AI35=AH35,1,0) -> 1
A36: =AJ36 -> 1 | F36: =IF(AJ36=1,"✅ "&AG36,"⬜ "&AG36) -> ✅ Expense Growth | AG36: Expense Growth | AH36: 1 | AI36: =IF(SUM('UW Model'!N113:Q113)>0,1,0) -> 1 | AJ36: =IF(AI36=AH36,1,0) -> 1
A37: =AJ37 -> 1 | F37: =IF(AJ37=1,"✅ "&AG37,"⬜ "&AG37) -> ✅ Tax Growth | AG37: Tax Growth | AH37: 1 | AI37: =IF(SUM('UW Model'!N114:Q114)>0,1,0) -> 1 | AJ37: =IF(AI37=AH37,1,0) -> 1

Sheet UW Model
E2: Offer Price | G2: Price / Unit | I2: Cap (at purchase) | K2: Total Units | M2: Interior Renovation Strategy | O2: CoC (LP) | Q2: AAR (LP) | S2: IRR (LP) | U2: EMx (LP)
E3: =IFERROR(G12,"") -> 0 | G3: =IFERROR(G12/H43,0) -> 0 | I3: =IFERROR(J94/G12,0) -> 0 | K3: =IFERROR(H43,"") -> 0 | M3: =TEXT(O43,"#,##")& " units • "&TEXT(P43/1000,"$0.0")&"k/unit • " &TEXT(S43,"0%")&" ROI" -> units • $0.0k/unit • 0% ROI | O3: =IFERROR(I196,0) -> 0 | Q3: =IFERROR(I204,0) -> 0 | S3: =IFERROR(I207,0) -> 0 | U3: =IFERROR(I208,0) -> 0
C5: DEAL ASSUMPTIONS | V5: Video Tutorial ▶️
C6: 1. PROPERTY INFORMATION | H6: 4. DEBT STRUCTURE | L6: 5. DEAL STRUCTURE | P6: KPIs | T6: UNDERWRITING NOTES
C7: Name | H7: Acquisition Loan Amount | K7: =K8*G12 -> 0 | L7: Preferred Return | O7: 0.08 | P7: LP CoC | R7: 0.07 | S7: =IFERROR(ROUND(I196,3),0) -> 0 | T7: Use this section to document all UW assumptions, findings, anomalies, & conclusions
C8: Address | H8: Loan to Value (LTV) | J8: =IFERROR(IF(_xlfn.ISFORMULA(K7)=TRUE,"",K7/G12),"") | K8: 0 | L8: Partner Split | N8: =1-O8 -> 0.7 | O8: 0.3 | P8: LP IRR | R8: 0.15 | S8: =ROUND(S3,3) -> 0
C9: Year Built | F9: Occupancy | G9: 1 | H9: Interest Rate | K9: 0 | L9: Acquisition Fee | N9: =J215 -> 0 | O9: 0.02 | P9: LP Equity Multiple (EMx) | R9: 1.65 | S9: =IFERROR(I208,0) -> 0
C10: 2. PURCHASE ASSUMPTIONS | H10: Loan Fee | J10: =K10*K7 -> 0 | K10: 0 | L10: Asset Mgt Fee | N10: =I216 -> 0 | O10: 0.02 | P10: Min DSCR | R10: 1.25 | S10: =IFERROR(MIN(K143:V143),0) -> 0
C11: Whisper Price | F11: =IFERROR(TEXT(G11/$A$43,"#")&" /SF" & " · "&TEXT(G11/$H$43/1000,"#,##")&"k /unit","") | H11: I/O Period | K11: 0 | L11: Refinance Fee | N11: =I217 -> 0 | O11: 0 | P11: Negative Cash Flow | S11: =IF(MIN(K142:V142)<0,"CHECK","OK") -> OK
C12: Offer Price | F12: =IFERROR(TEXT(G12/$A$43,"#")&" /SF" & " · "&TEXT(G12/$H$43/1000,"#,##")&"k /unit","") | H12: Amortization | K12: 30 | L12: Disposition Fee | N12: =IFERROR(I218,0) -> 0 | O12: 0 | P12: All Capital Returned | S12: =IF(MAX(K165:V165)=100%,"OK","CHECK") -> CHECK
C13: Acquisition Date | G13: =EDATE(NOW(),3) -> 45163 | H13: DSCR In-Place | I13: =IFERROR(J143,0) -> 0 | J13: DSCR Yr 1 | K13: =IFERROR(M143,0) -> 0 | L13: 6. RENOVATION ASSUMPTIONS | P13: SOURCES & USES
C14: Cap Rate (Market) | G14: 0.05 | H14: Refinance Loan Amount | J14: =IF(K15>1,IF(HLOOKUP(K15,C148:V159,12,0)<0,"ERROR",""),"") | K14: =IFERROR(HLOOKUP(K15,$K$77:$V$96,20,0)*K16,"0") -> 0 | L14: Interior Renovation Start Month | O14: 2 | P14: Sources | Q14: Loan | R14: =IFERROR(S14/S16,0) -> 0 | S14: =K7 -> 0
C15: Cap Rate (Yr1 Proforma) | G15: =IFERROR(M94/G12,0) -> 0 | H15: Refinance End of Year | L15: Interior Renovation End Month | O15: 12 | Q15: Equity | R15: =IFERROR(S15/S16,0) -> 0 | S15: =S23-S14 -> 0
C16: Closing Costs | F16: =G12*G16 -> 0 | G16: 0.025 | H16: Loan to Value (LTV) | J16: =IFERROR(IF(_xlfn.ISFORMULA(K14)=TRUE,"",K14/HLOOKUP(K15,$K$77:$V$96,20,0)),"") | K16: 0 | L16: Unit Renovations per Month | O16: =O43/(O15-1-O14) -> 0 | P16: TOTAL SOURCES | R16: =IFERROR(SUM(R14:R15),0) -> 0 | S16: =SUM(S14:S15) -> 0
C17: Operating Reserves | F17: =IFERROR(G17/('UW Model'!$M$88/12),0) -> 0 | G17: =IF(V6="ON",V17*V8*0.5,M88*0.5) -> 0 | H17: Interest Rate | K17: 0.06 | L17: Interior Renovation Completions per Year:
C18: Lender CapEx Reserves | G18: 250 | H18: Refinance Fee | J18: =K14*K18 -> 0 | K18: 0.015 | L18: ='GPR Logic'!R5 -> 0 | M18: ='GPR Logic'!S5-'GPR Logic'!R5 -> 0 | N18: ='GPR Logic'!T5-'GPR Logic'!S5 -> 0 | O18: =SUM(L18:N18) -> 0 | P18: Uses | Q18: Acquisition | R18: =IFERROR(S18/$S$23,0) -> 0 | S18: =G12 -> 0
A19: Sale Price | C19: 3. EXIT ASSUMPTIONS | H19: I/O Period | K19: 0 | L19: Renovation Costs | N19: /SF · /unit | O19: Total | Q19: All Closing Costs | R19: =IFERROR(S19/$S$23,0) -> 0 | S19: =J10+F16 -> 0
A20: =IFERROR(VLOOKUP("Property Value",$G$77:$V$100,MATCH(G20,$G$77:$V$77,0),0),0) -> 0 | B20: =IF('IRR Sensitivity'!C3="",G23,'IRR Sensitivity'!C3) -> 0.0575 | C20: Sale Year | F20: =IFERROR(TEXT(A20/A43,"#"),0)&" /SF · "&IFERROR(TEXT(ROUND((A20/H43)/1000,0),"#,##"),0) &"k /unit · "&IFERROR(TEXT(ROUND(A20/1000000,1),"0.0"),0)&"M" -> 0 /SF · 0k /unit · 0.0M | G20: 5 | H20: Amortization | K20: 30 | L20: Interior Reno Cost | N20: =IFERROR(TEXT(Q43/SUMIF(O28:O42,">0",A28:A42),"0.00") &" · " & TEXT(IFERROR(P43,0),"0,##"),"") | O20: =Q43 -> 0 | Q20: Renovation Costs | R20: =IFERROR(S20/$S$23,0) -> 0 | S20: =O23 -> 0
C21: Sale Costs | F21: =IFERROR(HLOOKUP(MATCH(G20,$M$148:$V$148,0),$M$148:$V$155,8,0),0) -> 0 | G21: 0.03 | H21: Cap Rate at Refinance | K21: =IFERROR(HLOOKUP(K15,$K$77:$V$96,MATCH("Market CAP Rate",$G$77:$G$96,0),0),0) -> 0 | L21: Exterior Reno Cost | N21: =IFERROR(TEXT(O21/SUMIF(H28:H42,">0",A28:A42),"0.00") &" · " &TEXT(IFERROR(O21/H43,0),"0,##"),"") | O21: 0 | Q21: Operating Reserves | R21: =IFERROR(S21/$S$23,0) -> 0 | S21: =G17 -> 0
C22: Reserves Returned at Sale | F22: =G22*G17 -> 0 | G22: 0.5 | H22: Value at Refinance | K22: =IFERROR(HLOOKUP(K15,$K$77:$V$96,MATCH("Property Value",$G$77:$G$96,0),0),0) -> 0 | L22: Contingency | M22: 0 | N22: =IFERROR(TEXT(O22/SUMIF(H28:H42,">0",A28:A42),"0.00") &" · " &TEXT(IFERROR(O22/H43,0),"0,##"),"") | O22: =M22*(O21+O20) -> 0 | Q22: Acquisition Fee | R22: =IFERROR(S22/$S$23,0) -> 0 | S22: =G12*O9 -> 0
C23: Sale / Exit Cap Rate | F23: 0.0015 | G23: =(F23*G20)+G14 -> 0.0575 | H23: ="DSCR Yr "&IF(OR(K15=0,K15="")," - ",K15+1) -> DSCR Yr - | I23: =IFERROR(HLOOKUP(K15+1,$N$123:$V$143,MATCH("DSCR",$G$123:$G$143,0),0),0) -> 0 | K23: ="Return of Capital "&TEXT(HLOOKUP(K15,C148:V165,MATCH("% of Capital Returned",$C$148:$C$165,0),0),"0.0%") -> Return of Capital 0.0% | L23: TOTAL RENO | N23: =IFERROR(TEXT(O23/SUMIF(H28:H42,">0",A28:A42),"0.00") &" · " &TEXT(IFERROR(O23/H43,0),"0,##"),"") | O23: =SUM(O20:O22) -> 0 | P23: TOTAL USES | R23: =IFERROR(SUM(R18:R22),0) -> 0 | S23: =SUM(S18:S22) -> 0
C25: UNIT MIX, RENT, & INTERIOR RENOVATION STRATEGY | V25: Video Tutorial ▶️
C26: UNIT TYPE INFORMATION | I26: IN PLACE RENTS | L26: CURRENT MARKET RENTS | O26: RENOVATION PLAN | T26: POST-RENOVATION RENTS
A27: NRA SF | C27: Unit Type | D27: Reno? | E27: Beds | F27: Baths | G27: Avg. SF | H27: # of Units | I27: /Unit/Mo | J27: /SF/Mo | K27: Total/Mo | L27: /Unit/Mo | M27: /SF/Mo | N27: Total/Mo | O27: Units to Renovate | P27: Cost /unit | Q27: Total Reno Cost | R27: Rent Premium /unit | S27: 1 Year ROI | T27: /Unit/Mo | U27: /SF/Mo | V27: Total/Mo
A28: =IF(G28="","",G28*H28) | C28: =IF(H28>0,E28&"/"&F28&" "&TEXT(G28,"#,##")&"sf"&IF(D28="Y"," - R",""),"") | J28: =IFERROR(IF(I28="","",I28/$G28),"") | K28: =IF(I28="","",I28*$H28) | M28: =IFERROR(IF(L28="","",L28/$G28),"") | N28: =IF(L28="","",L28*$H28) | Q28: =IF(O28<1,"",O28*P28) | S28: =IFERROR(IF(O28>0,(R28*12)/P28,""),0) | T28: =IF(H28>0,V28/H28,"") | U28: =IFERROR(IF(T28="","",T28/$G28),0) | V28: =IF(O28="",N28,(L28*(H28-O28)+(O28*(L28+R28))))
A29: =IF(G29="","",G29*H29) | C29: =IF(H29>0,E29&"/"&F29&" "&TEXT(G29,"#,##")&"sf"&IF(D29="Y"," - R",""),"") | J29: =IFERROR(IF(I29="","",I29/$G29),"") | K29: =IF(I29="","",I29*$H29) | M29: =IFERROR(IF(L29="","",L29/$G29),"") | N29: =IF(L29="","",L29*$H29) | Q29: =IF(O29<1,"",O29*P29) | S29: =IFERROR(IF(O29>0,(R29*12)/P29,""),0) | T29: =IF(H29>0,V29/H29,"") | U29: =IFERROR(IF(T29="","",T29/$G29),0) | V29: =IF(O29="",N29,(L29*(H29-O29)+(O29*(L29+R29))))
A30: =IF(G30="","",G30*H30) | C30: =IF(H30>0,E30&"/"&F30&" "&TEXT(G30,"#,##")&"sf"&IF(D30="Y"," - R",""),"") | J30: =IFERROR(IF(I30="","",I30/$G30),"") | K30: =IF(I30="","",I30*$H30) | M30: =IFERROR(IF(L30="","",L30/$G30),"") | N30: =IF(L30="","",L30*$H30) | Q30: =IF(O30<1,"",O30*P30) | S30: =IFERROR(IF(O30>0,(R30*12)/P30,""),0) | T30: =IF(H30>0,V30/H30,"") | U30: =IFERROR(IF(T30="","",T30/$G30),0) | V30: =IF(O30="",N30,(L30*(H30-O30)+(O30*(L30+R30))))
A31: =IF(G31="","",G31*H31) | C31: =IF(H31>0,E31&"/"&F31&" "&TEXT(G31,"#,##")&"sf"&IF(D31="Y"," - R",""),"") | J31: =IFERROR(IF(I31="","",I31/$G31),"") | K31: =IF(I31="","",I31*$H31) | M31: =IFERROR(IF(L31="","",L31/$G31),"") | N31: =IF(L31="","",L31*$H31) | Q31: =IF(O31<1,"",O31*P31) | S31: =IFERROR(IF(O31>0,(R31*12)/P31,""),0) | T31: =IF(H31>0,V31/H31,"") | U31: =IFERROR(IF(T31="","",T31/$G31),0) | V31: =IF(O31="",N31,(L31*(H31-O31)+(O31*(L31+R31))))
A32: =IF(G32="","",G32*H32) | C32: =IF(H32>0,E32&"/"&F32&" "&TEXT(G32,"#,##")&"sf"&IF(D32="Y"," - R",""),"") | J32: =IFERROR(IF(I32="","",I32/$G32),"") | K32: =IF(I32="","",I32*$H32) | M32: =IFERROR(IF(L32="","",L32/$G32),"") | N32: =IF(L32="","",L32*$H32) | Q32: =IF(O32<1,"",O32*P32) | S32: =IFERROR(IF(O32>0,(R32*12)/P32,""),0) | T32: =IF(H32>0,V32/H32,"") | U32: =IFERROR(IF(T32="","",T32/$G32),0) | V32: =IF(O32="",N32,(L32*(H32-O32)+(O32*(L32+R32))))
A33: =IF(G33="","",G33*H33) | C33: =IF(H33>0,E33&"/"&F33&" "&TEXT(G33,"#,##")&"sf"&IF(D33="Y"," - R",""),"") | J33: =IFERROR(IF(I33="","",I33/$G33),"") | K33: =IF(I33="","",I33*$H33) | M33: =IFERROR(IF(L33="","",L33/$G33),"") | N33: =IF(L33="","",L33*$H33) | Q33: =IF(O33<1,"",O33*P33) | S33: =IFERROR(IF(O33>0,(R33*12)/P33,""),0) | T33: =IF(H33>0,V33/H33,"") | U33: =IFERROR(IF(T33="","",T33/$G33),0) | V33: =IF(O33="",N33,(L33*(H33-O33)+(O33*(L33+R33))))
A34: =IF(G34="","",G34*H34) | C34: =IF(H34>0,E34&"/"&F34&" "&TEXT(G34,"#,##")&"sf"&IF(D34="Y"," - R",""),"") | J34: =IFERROR(IF(I34="","",I34/$G34),"") | K34: =IF(I34="","",I34*$H34) | M34: =IFERROR(IF(L34="","",L34/$G34),"") | N34: =IF(L34="","",L34*$H34) | Q34: =IF(O34<1,"",O34*P34) | S34: =IFERROR(IF(O34>0,(R34*12)/P34,""),0) | T34: =IF(H34>0,V34/H34,"") | U34: =IFERROR(IF(T34="","",T34/$G34),0) | V34: =IF(O34="",N34,(L34*(H34-O34)+(O34*(L34+R34))))
A35: =IF(G35="","",G35*H35) | C35: =IF(H35>0,E35&"/"&F35&" "&TEXT(G35,"#,##")&"sf"&IF(D35="Y"," - R",""),"") | J35: =IFERROR(IF(I35="","",I35/$G35),"") | K35: =IF(I35="","",I35*$H35) | M35: =IFERROR(IF(L35="","",L35/$G35),"") | N35: =IF(L35="","",L35*$H35) | Q35: =IF(O35<1,"",O35*P35) | S35: =IFERROR(IF(O35>0,(R35*12)/P35,""),0) | T35: =IF(H35>0,V35/H35,"") | U35: =IFERROR(IF(T35="","",T35/$G35),0) | V35: =IF(O35="",N35,(L35*(H35-O35)+(O35*(L35+R35))))
A36: =IF(G36="","",G36*H36) | C36: =IF(H36>0,E36&"/"&F36&" "&TEXT(G36,"#,##")&"sf"&IF(D36="Y"," - R",""),"") | J36: =IFERROR(IF(I36="","",I36/$G36),"") | K36: =IF(I36="","",I36*$H36) | M36: =IFERROR(IF(L36="","",L36/$G36),"") | N36: =IF(L36="","",L36*$H36) | Q36: =IF(O36<1,"",O36*P36) | S36: =IFERROR(IF(O36>0,(R36*12)/P36,""),0) | T36: =IF(H36>0,V36/H36,"") | U36: =IFERROR(IF(T36="","",T36/$G36),0) | V36: =IF(O36="",N36,(L36*(H36-O36)+(O36*(L36+R36))))
A37: =IF(G37="","",G37*H37) | C37: =IF(H37>0,E37&"/"&F37&" "&TEXT(G37,"#,##")&"sf"&IF(D37="Y"," - R",""),"") | J37: =IFERROR(IF(I37="","",I37/$G37),"") | K37: =IF(I37="","",I37*$H37) | M37: =IFERROR(IF(L37="","",L37/$G37),"") | N37: =IF(L37="","",L37*$H37) | Q37: =IF(O37<1,"",O37*P37) | S37: =IFERROR(IF(O37>0,(R37*12)/P37,""),0) | T37: =IF(H37>0,V37/H37,"") | U37: =IFERROR(IF(T37="","",T37/$G37),0) | V37: =IF(O37="",N37,(L37*(H37-O37)+(O37*(L37+R37))))
A38: =IF(G38="","",G38*H38) | C38: =IF(H38>0,E38&"/"&F38&" "&TEXT(G38,"#,##")&"sf"&IF(D38="Y"," - R",""),"") | J38: =IFERROR(IF(I38="","",I38/$G38),"") | K38: =IF(I38="","",I38*$H38) | M38: =IFERROR(IF(L38="","",L38/$G38),"") | N38: =IF(L38="","",L38*$H38) | Q38: =IF(O38<1,"",O38*P38) | S38: =IFERROR(IF(O38>0,(R38*12)/P38,""),0) | T38: =IF(H38>0,V38/H38,"") | U38: =IFERROR(IF(T38="","",T38/$G38),0) | V38: =IF(O38="",N38,(L38*(H38-O38)+(O38*(L38+R38))))
A39: =IF(G39="","",G39*H39) | C39: =IF(H39>0,E39&"/"&F39&" "&TEXT(G39,"#,##")&"sf"&IF(D39="Y"," - R",""),"") | J39: =IFERROR(IF(I39="","",I39/$G39),"") | K39: =IF(I39="","",I39*$H39) | M39: =IFERROR(IF(L39="","",L39/$G39),"") | N39: =IF(L39="","",L39*$H39) | Q39: =IF(O39<1,"",O39*P39) | S39: =IFERROR(IF(O39>0,(R39*12)/P39,""),0) | T39: =IF(H39>0,V39/H39,"") | U39: =IFERROR(IF(T39="","",T39/$G39),0) | V39: =IF(O39="",N39,(L39*(H39-O39)+(O39*(L39+R39))))
... A42: =IF(G42="","",G42*H42) | C42: =IF(H42>0,E42&"/"&F42&" "&TEXT(G42,"#,##")&"sf"&IF(D42="Y"," - R",""),"") | J42: =IFERROR(IF(I42="","",I42/$G42),"") | K42: =IF(I42="","",I42*$H42) | M42: =IFERROR(IF(L42="","",L42/$G42),"") | N42: =IF(L42="","",L42*$H42) | Q42: =IF(O42<1,"",O42*P42) | S42: =IFERROR(IF(O42>0,(R42*12)/P42,""),0) | T42: =IF(H42>0,V42/H42,"") | U42: =IFERROR(IF(T42="","",T42/$G42),0) | V42: =IF(O42="",N42,(L42*(H42-O42)+(O42*(L42+R42))))
A43: =IF(V6="ON",V10,SUM(A28:A42)) -> 0 | C43: Average / Total | G43: =IFERROR(IF($V$6="ON",V9,A43/H43),0) -> 0 | H43: =IF(V6="ON",V8,SUM(H28:H42)) -> 0 | I43: =IFERROR(K43/H43,0) -> 0 | J43: =IFERROR(K43/$A43,0) -> 0 | K43: =IF(S6="ON",S7*S12,SUM(K28:K42)) -> 0 | L43: =IFERROR(IF(V8="ON",V13,N43/$H43),0) -> 0 | M43: =IFERROR(N43/$A43,0) -> 0 | N43: =IF(V6="ON",V8*V13,SUM(N28:N42)) -> 0 | O43: =IF(V6="ON",V20,SUM(O28:O42)) -> 0 | P43: =IFERROR(IF(V6="ON",V22,Q43/O43),0) -> 0 | Q43: =IF(V6="ON",V20*V22,SUM(Q28:Q42)) -> 0 | R43: =IFERROR(IF(V6="ON",V21,SUMPRODUCT(O28:O42,R28:R42)/O43),0) -> 0 | S43: =IFERROR((R43*12)/P43,0) -> 0 | T43: =IFERROR(IF(V6="ON",((V20*(V13+V21))+((V8-V20)*V13))/V8,V43/$H43),0) -> 0 | U43: =IFERROR(T43/$G43,0) -> 0 | V43: =IF(V6="ON",T43*H43,SUM(V28:V42)) -> 0
J44: Annual GPR | K44: =K43*12 -> 0 | L44: =(N43-K43)*12 -> 0 | M44: Annual GPR | N44: =N43*12 -> 0 | R44: =IFERROR(TEXT(R43,"$#,##")&" / "&TEXT(R43/(SUMPRODUCT(O28:O42,L28:L42)/O43),"0%"),0) -> 0 | T44: =IFERROR(TEXT(T43-L43,"$#,##")& " / " & TEXT(T43/L43-1,"0%"),0) -> 0 | U44: Annual GPR | V44: =V43*12 -> 0
C46: INCOME | V46: Video Tutorial ▶️
...

Sheet IRR Sensitivity
B2: Inputs | F2: Data Table | K2: Baseline
B3: Exit Cap | D3: ='UW Model'!B20 -> 0.0575 | F3: Exit Cap Rate | H3: =I3-$D$4 -> 0.053 | I3: =J3-$D$4 -> 0.0545 | J3: =K3-$D$4 -> 0.056 | K3: ='UW Model'!G23 -> 0.0575 | L3: =K3+$D$4 -> 0.059 | M3: =L3+$D$4 -> 0.0605 | N3: =M3+$D$4 -> 0.062
B4: Cap Escalator | D4: =('UW Model'!G23-'UW Model'!G14)/'UW Model'!G20 -> 0.0015 | F4: IRR (LP) | G4: ='UW Model'!I207 -> 0 | H4: 0 | I4: 0 | J4: 0 | K4: 0 | L4: 0 | M4: 0 | N4: 0
B5: Exit Year | D5: ='UW Model'!G20 -> 5

Sheet Administrative -->

Sheet GPR Logic
B1: Video Tutorial ▶️ | W1: =IF(W3='UW Model'!$O$14,"Reno Start", IF(AND(W3>'UW Model'!$O$14,W3<'UW Model'!$O$15),"Rolling", IF(W3='UW Model'!$O$15,"Reno End",""))) | X1: =IF(X3='UW Model'!$O$14,"Reno Start", IF(AND(X3>'UW Model'!$O$14,X3<'UW Model'!$O$15),"Rolling", IF(X3='UW Model'!$O$15,"Reno End",""))) | Y1: =IF(Y3='UW Model'!$O$14,"Reno Start", IF(AND(Y3>'UW Model'!$O$14,Y3<'UW Model'!$O$15),"Rolling", IF(Y3='UW Model'!$O$15,"Reno End",""))) -> Reno Start | Z1: =IF(Z3='UW Model'!$O$14,"Reno Start", IF(AND(Z3>'UW Model'!$O$14,Z3<'UW Model'!$O$15),"Rolling", IF(Z3='UW Model'!$O$15,"Reno End",""))) -> Rolling | AA1: =IF(AA3='UW Model'!$O$14,"Reno Start", IF(AND(AA3>'UW Model'!$O$14,AA3<'UW Model'!$O$15),"Rolling", IF(AA3='UW Model'!$O$15,"Reno End",""))) -> Rolling | AB1: =IF(AB3='UW Model'!$O$14,"Reno Start", IF(AND(AB3>'UW Model'!$O$14,AB3<'UW Model'!$O$15),"Rolling", IF(AB3='UW Model'!$O$15,"Reno End",""))) -> Rolling | AC1: =IF(AC3='UW Model'!$O$14,"Reno Start", IF(AND(AC3>'UW Model'!$O$14,AC3<'UW Model'!$O$15),"Rolling", IF(AC3='UW Model'!$O$15,"Reno End",""))) -> Rolling | AD1: =IF(AD3='UW Model'!$O$14,"Reno Start", IF(AND(AD3>'UW Model'!$O$14,AD3<'UW Model'!$O$15),"Rolling", IF(AD3='UW Model'!$O$15,"Reno End",""))) -> Rolling | ... CE1: =IF(CE3='UW Model'!$O$14,"Reno Start", IF(AND(CE3>'UW Model'!$O$14,CE3<'UW Model'!$O$15),"Rolling", IF(CE3='UW Model'!$O$15,"Reno End","")))
B2: INTERIOR RENOVATION GRAPHS | F2: The purpose of this tab is to reveal the logic utilized by the UW model to determine Gross Potential Rent (GPR) and Renovation Vacancy. Each unit type that is to be renovated is moved to Reno Vacancy for 2 months & then moved to the post-renovation revenue based on the renovation start & duration set on the UW Model tab. The below graph helps to illustrate this process | Q2: Year | R2: 1 | S2: 2 | T2: 3 | U2: 4 | V2: 5 | W2: 0 | X2: 1 | Y2: 1 | Z2: 1 | AA2: 1 | AB2: 1 | AC2: 1 | AD2: 1 | AE2: 1 | AF2: 1 | AG2: 1 | AH2: 1 | AI2: 1 | AJ2: 2 | AK2: 2 | AL2: 2 | AM2: 2 | AN2: 2 | AO2: 2 | AP2: 2 | AQ2: 2 | AR2: 2 | AS2: 2 | AT2: 2 | AU2: 2 | AV2: 3 | AW2: 3 | AX2: 3 | AY2: 3 | AZ2: 3 | BA2: 3 | BB2: 3 | BC2: 3 | BD2: 3 | BE2: 3 | BF2: 3 | BG2: 3 | BH2: 4 | BI2: 4 | BJ2: 4 | BK2: 4 | BL2: 4 | BM2: 4 | BN2: 4 | BO2: 4 | BP2: 4 | BQ2: 4 | BR2: 4 | BS2: 4 | BT2: 5 | BU2: =BT2 -> 5 | BV2: =BU2 -> 5 | BW2: =BV2 -> 5 | BX2: =BW2 -> 5 | BY2: =BX2 -> 5 | BZ2: =BY2 -> 5 | CA2: =BZ2 -> 5 | CB2: =CA2 -> 5 | ... CE2: =CD2 -> 5
Q3: Month | R3: N/A | S3: N/A | T3: N/A | U3: N/A | V3: N/A | W3: 0 | X3: 1 | Y3: 2 | Z3: 3 | AA3: 4 | AB3: 5 | AC3: 6 | AD3: 7 | AE3: 8 | AF3: 9 | AG3: 10 | AH3: 11 | AI3: 12 | AJ3: 13 | AK3: 14 | AL3: 15 | AM3: 16 | AN3: 17 | AO3: 18 | AP3: 19 | AQ3: 20 | AR3: 21 | AS3: 22 | AT3: 23 | AU3: 24 | AV3: 25 | AW3: 26 | AX3: 27 | AY3: 28 | AZ3: 29 | BA3: 30 | BB3: 31 | BC3: 32 | BD3: 33 | BE3: 34 | BF3: 35 | BG3: 36 | BH3: =BG3+1 -> 37 | BI3: =BH3+1 -> 38 | BJ3: =BI3+1 -> 39 | BK3: =BJ3+1 -> 40 | BL3: =BK3+1 -> 41 | BM3: =BL3+1 -> 42 | BN3: =BM3+1 -> 43 | BO3: =BN3+1 -> 44 | ... CE3: =CD3+1 -> 60
Q4: Date | R4: =_xlfn.MAXIFS($X4:$BS4,$X$2:$BS$2,R$2) -> 45529 | S4: =_xlfn.MAXIFS($X4:$BS4,$X$2:$BS$2,S$2) -> 45894 | T4: =_xlfn.MAXIFS($X4:$BS4,$X$2:$BS$2,T$2) -> 46259 | U4: =_xlfn.MAXIFS($X4:$BS4,$X$2:$BS$2,U$2) -> 46624 | V4: =_xlfn.MAXIFS($X4:$CE4,$X$2:$CE$2,V$2) -> 46990 | W4: ='UW Model'!G13 -> 45163 | X4: =EDATE(W4,1) -> 45194 | Y4: =EDATE(X4,1) -> 45224 | Z4: =EDATE(Y4,1) -> 45255 | AA4: =EDATE(Z4,1) -> 45285 | AB4: =EDATE(AA4,1) -> 45316 | AC4: =EDATE(AB4,1) -> 45347 | AD4: =EDATE(AC4,1) -> 45376 | AE4: =EDATE(AD4,1) -> 45407 | ... CE4: =EDATE(CD4,1) -> 46990
P5: Gross Rents for Planned Renovations | Q5: Reno Unit Completions Total | R5: =SUM(R6:R20) -> 0 | S5: =SUM(S6:S20) -> 0 | T5: =SUM(T6:T20) -> 0 | U5: =SUM(U6:U20) -> 0 | V5: =SUM(V6:V20) -> 0 | W5: =SUM(W6:W20) -> 0 | X5: =SUM(X6:X20) -> 0 | Y5: =SUM(Y6:Y20) -> 0 | ... CE5: =SUM(CE6:CE20) -> 0
Q6: =IF('UW Model'!C28="","",'UW Model'!C28) | R6: =_xlfn.MAXIFS($X6:$CE6,$X$2:$CE$2,R$2) -> 0 | S6: =_xlfn.MAXIFS($X6:$CE6,$X$2:$CE$2,S$2) -> 0 | T6: =_xlfn.MAXIFS($X6:$CE6,$X$2:$CE$2,T$2) -> 0 | U6: =_xlfn.MAXIFS($X6:$CE6,$X$2:$CE$2,U$2) -> 0 | V6: =_xlfn.MAXIFS($X6:$CE6,$X$2:$CE$2,V$2) -> 0 | W6: 0 | X6: =IF(AND(X$3>'UW Model'!$O$14+1,X$3<='UW Model'!$O$15),'UW Model'!$O28/('UW Model'!$O$15-'UW Model'!$O$14-1)+W6,0) -> 0 | Y6: =IF(AND(Y$3>'UW Model'!$O$14+1,Y$3<='UW Model'!$O$15),'UW Model'!$O28/('UW Model'!$O$15-'UW Model'!$O$14-1)+X6,X6) -> 0 | Z6: =IF(AND(Z$3>'UW Model'!$O$14+1,Z$3<='UW Model'!$O$15),'UW Model'!$O28/('UW Model'!$O$15-'UW Model'!$O$14-1)+Y6,Y6) -> 0 | AA6: =IF(AND(AA$3>'UW Model'!$O$14+1,AA$3<='UW Model'!$O$15),'UW Model'!$O28/('UW Model'!$O$15-'UW Model'!$O$14-1)+Z6,Z6) -> 0 | AB6: =IF(AND(AB$3>'UW Model'!$O$14+1,AB$3<='UW Model'!$O$15),'UW Model'!$O28/('UW Model'!$O$15-'UW Model'!$O$14-1)+AA6,AA6) -> 0 | AC6: =IF(AND(AC$3>'UW Model'!$O$14+1,AC$3<='UW Model'!$O$15),'UW Model'!$O28/('UW Model'!$O$15-'UW Model'!$O$14-1)+AB6,AB6) -> 0 | AD6: =IF(AND(AD$3>'UW Model'!$O$14+1,AD$3<='UW Model'!$O$15),'UW Model'!$O28/('UW Model'!$O$15-'UW Model'!$O$14-1)+AC6,AC6) -> 0 | AE6: =IF(AND(AE$3>'UW Model'!$O$14+1,AE$3<='UW Model'!$O$15),'UW Model'!$O28/('UW Model'!$O$15-'UW Model'!$O$14-1)+AD6,AD6) -> 0 | AF6: =IF(AND(AF$3>'UW Model'!$O$14+1,AF$3<='UW Model'!$O$15),'UW Model'!$O28/('UW Model'!$O$15-'UW Model'!$O$14-1)+AE6,AE6) -> 0 | ... CE6: =IF(AND(CE$3>'UW Model'!$O$14+1,CE$3<='UW Model'!$O$15),'UW Model'!$O28/('UW Model'!$O$15-'UW Model'!$O$14-1)+CD6,CD6) -> 0
Q7: =IF('UW Model'!C29="","",'UW Model'!C29) | R7: =_xlfn.MAXIFS($X7:$CE7,$X$2:$CE$2,R$2) -> 0 | S7: =_xlfn.MAXIFS($X7:$CE7,$X$2:$CE$2,S$2) -> 0 | T7: =_xlfn.MAXIFS($X7:$CE7,$X$2:$CE$2,T$2) -> 0 | U7: =_xlfn.MAXIFS($X7:$CE7,$X$2:$CE$2,U$2) -> 0 | V7: =_xlfn.MAXIFS($X7:$CE7,$X$2:$CE$2,V$2) -> 0 | W7: 0 | X7: =IF(AND(X$3>'UW Model'!$O$14+1,X$3<='UW Model'!$O$15),'UW Model'!$O29/('UW Model'!$O$15-'UW Model'!$O$14-1)+W7,0) -> 0 | Y7: =IF(AND(Y$3>'UW Model'!$O$14+1,Y$3<='UW Model'!$O$15),'UW Model'!$O29/('UW Model'!$O$15-'UW Model'!$O$14-1)+X7,X7) -> 0 | Z7: =IF(AND(Z$3>'UW Model'!$O$14+1,Z$3<='UW Model'!$O$15),'UW Model'!$O29/('UW Model'!$O$15-'UW Model'!$O$14-1)+Y7,Y7) -> 0 | AA7: =IF(AND(AA$3>'UW Model'!$O$14+1,AA$3<='UW Model'!$O$15),'UW Model'!$O29/('UW Model'!$O$15-'UW Model'!$O$14-1)+Z7,Z7) -> 0 | AB7: =IF(AND(AB$3>'UW Model'!$O$14+1,AB$3<='UW Model'!$O$15),'UW Model'!$O29/('UW Model'!$O$15-'UW Model'!$O$14-1)+AA7,AA7) -> 0 | AC7: =IF(AND(AC$3>'UW Model'!$O$14+1,AC$3<='UW Model'!$O$15),'UW Model'!$O29/('UW Model'!$O$15-'UW Model'!$O$14-1)+AB7,AB7) -> 0 | AD7: =IF(AND(AD$3>'UW Model'!$O$14+1,AD$3<='UW Model'!$O$15),'UW Model'!$O29/('UW Model'!$O$15-'UW Model'!$O$14-1)+AC7,AC7) -> 0 | AE7: =IF(AND(AE$3>'UW Model'!$O$14+1,AE$3<='UW Model'!$O$15),'UW Model'!$O29/('UW Model'!$O$15-'UW Model'!$O$14-1)+AD7,AD7) -> 0 | AF7: =IF(AND(AF$3>'UW Model'!$O$14+1,AF$3<='UW Model'!$O$15),'UW Model'!$O29/('UW Model'!$O$15-'UW Model'!$O$14-1)+AE7,AE7) -> 0 | ... CE7: =IF(AND(CE$3>'UW Model'!$O$14+1,CE$3<='UW Model'!$O$15),'UW Model'!$O29/('UW Model'!$O$15-'UW Model'!$O$14-1)+CD7,CD7) -> 0
Q8: =IF('UW Model'!C30="","",'UW Model'!C30) | R8: =_xlfn.MAXIFS($X8:$CE8,$X$2:$CE$2,R$2) -> 0 | S8: =_xlfn.MAXIFS($X8:$CE8,$X$2:$CE$2,S$2) -> 0 | T8: =_xlfn.MAXIFS($X8:$CE8,$X$2:$CE$2,T$2) -> 0 | U8: =_xlfn.MAXIFS($X8:$CE8,$X$2:$CE$2,U$2) -> 0 | V8: =_xlfn.MAXIFS($X8:$CE8,$X$2:$CE$2,V$2) -> 0 | W8: 0 | X8: =IF(AND(X$3>'UW Model'!$O$14+1,X$3<='UW Model'!$O$15),'UW Model'!$O30/('UW Model'!$O$15-'UW Model'!$O$14-1)+W8,0) -> 0 | Y8: =IF(AND(Y$3>'UW Model'!$O$14+1,Y$3<='UW Model'!$O$15),'UW Model'!$O30/('UW Model'!$O$15-'UW Model'!$O$14-1)+X8,X8) -> 0 | Z8: =IF(AND(Z$3>'UW Model'!$O$14+1,Z$3<='UW Model'!$O$15),'UW Model'!$O30/('UW Model'!$O$15-'UW Model'!$O$14-1)+Y8,Y8) -> 0 | AA8: =IF(AND(AA$3>'UW Model'!$O$14+1,AA$3<='UW Model'!$O$15),'UW Model'!$O30/('UW Model'!$O$15-'UW Model'!$O$14-1)+Z8,Z8) -> 0 | AB8: =IF(AND(AB$3>'UW Model'!$O$14+1,AB$3<='UW Model'!$O$15),'UW Model'!$O30/('UW Model'!$O$15-'UW Model'!$O$14-1)+AA8,AA8) -> 0 | AC8: =IF(AND(AC$3>'UW Model'!$O$14+1,AC$3<='UW Model'!$O$15),'UW Model'!$O30/('UW Model'!$O$15-'UW Model'!$O$14-1)+AB8,AB8) -> 0 | AD8: =IF(AND(AD$3>'UW Model'!$O$14+1,AD$3<='UW Model'!$O$15),'UW Model'!$O30/('UW Model'!$O$15-'UW Model'!$O$14-1)+AC8,AC8) -> 0 | AE8: =IF(AND(AE$3>'UW Model'!$O$14+1,AE$3<='UW Model'!$O$15),'UW Model'!$O30/('UW Model'!$O$15-'UW Model'!$O$14-1)+AD8,AD8) -> 0 | AF8: =IF(AND(AF$3>'UW Model'!$O$14+1,AF$3<='UW Model'!$O$15),'UW Model'!$O30/('UW Model'!$O$15-'UW Model'!$O$14-1)+AE8,AE8) -> 0 | ... CE8: =IF(AND(CE$3>'UW Model'!$O$14+1,CE$3<='UW Model'!$O$15),'UW Model'!$O30/('UW Model'!$O$15-'UW Model'!$O$14-1)+CD8,CD8) -> 0
Q9: =IF('UW Model'!C31="","",'UW Model'!C31) | R9: =_xlfn.MAXIFS($X9:$CE9,$X$2:$CE$2,R$2) -> 0 | S9: =_xlfn.MAXIFS($X9:$CE9,$X$2:$CE$2,S$2) -> 0 | T9: =_xlfn.MAXIFS($X9:$CE9,$X$2:$CE$2,T$2) -> 0 | U9: =_xlfn.MAXIFS($X9:$CE9,$X$2:$CE$2,U$2) -> 0 | V9: =_xlfn.MAXIFS($X9:$CE9,$X$2:$CE$2,V$2) -> 0 | W9: 0 | X9: =IF(AND(X$3>'UW Model'!$O$14+1,X$3<='UW Model'!$O$15),'UW Model'!$O31/('UW Model'!$O$15-'UW Model'!$O$14-1)+W9,0) -> 0 | Y9: =IF(AND(Y$3>'UW Model'!$O$14+1,Y$3<='UW Model'!$O$15),'UW Model'!$O31/('UW Model'!$O$15-'UW Model'!$O$14-1)+X9,X9) -> 0 | Z9: =IF(AND(Z$3>'UW Model'!$O$14+1,Z$3<='UW Model'!$O$15),'UW Model'!$O31/('UW Model'!$O$15-'UW Model'!$O$14-1)+Y9,Y9) -> 0 | AA9: =IF(AND(AA$3>'UW Model'!$O$14+1,AA$3<='UW Model'!$O$15),'UW Model'!$O31/('UW Model'!$O$15-'UW Model'!$O$14-1)+Z9,Z9) -> 0 | AB9: =IF(AND(AB$3>'UW Model'!$O$14+1,AB$3<='UW Model'!$O$15),'UW Model'!$O31/('UW Model'!$O$15-'UW Model'!$O$14-1)+AA9,AA9) -> 0 | AC9: =IF(AND(AC$3>'UW Model'!$O$14+1,AC$3<='UW Model'!$O$15),'UW Model'!$O31/('UW Model'!$O$15-'UW Model'!$O$14-1)+AB9,AB9) -> 0 | AD9: =IF(AND(AD$3>'UW Model'!$O$14+1,AD$3<='UW Model'!$O$15),'UW Model'!$O31/('UW Model'!$O$15-'UW Model'!$O$14-1)+AC9,AC9) -> 0 | AE9: =IF(AND(AE$3>'UW Model'!$O$14+1,AE$3<='UW Model'!$O$15),'UW Model'!$O31/('UW Model'!$O$15-'UW Model'!$O$14-1)+AD9,AD9) -> 0 | AF9: =IF(AND(AF$3>'UW Model'!$O$14+1,AF$3<='UW Model'!$O$15),'UW Model'!$O31/('UW Model'!$O$15-'UW Model'!$O$14-1)+AE9,AE9) -> 0 | ... CE9: =IF(AND(CE$3>'UW Model'!$O$14+1,CE$3<='UW Model'!$O$15),'UW Model'!$O31/('UW Model'!$O$15-'UW Model'!$O$14-1)+CD9,CD9) -> 0
Q10: =IF('UW Model'!C32="","",'UW Model'!C32) | R10: =_xlfn.MAXIFS($X10:$CE10,$X$2:$CE$2,R$2) -> 0 | S10: =_xlfn.MAXIFS($X10:$CE10,$X$2:$CE$2,S$2) -> 0 | T10: =_xlfn.MAXIFS($X10:$CE10,$X$2:$CE$2,T$2) -> 0 | U10: =_xlfn.MAXIFS($X10:$CE10,$X$2:$CE$2,U$2) -> 0 | V10: =_xlfn.MAXIFS($X10:$CE10,$X$2:$CE$2,V$2) -> 0 | W10: 0 | X10: =IF(AND(X$3>'UW Model'!$O$14+1,X$3<='UW Model'!$O$15),'UW Model'!$O32/('UW Model'!$O$15-'UW Model'!$O$14-1)+W10,0) -> 0 | Y10: =IF(AND(Y$3>'UW Model'!$O$14+1,Y$3<='UW Model'!$O$15),'UW Model'!$O32/('UW Model'!$O$15-'UW Model'!$O$14-1)+X10,X10) -> 0 | Z10: =IF(AND(Z$3>'UW Model'!$O$14+1,Z$3<='UW Model'!$O$15),'UW Model'!$O32/('UW Model'!$O$15-'UW Model'!$O$14-1)+Y10,Y10) -> 0 | AA10: =IF(AND(AA$3>'UW Model'!$O$14+1,AA$3<='UW Model'!$O$15),'UW Model'!$O32/('UW Model'!$O$15-'UW Model'!$O$14-1)+Z10,Z10) -> 0 | AB10: =IF(AND(AB$3>'UW Model'!$O$14+1,AB$3<='UW Model'!$O$15),'UW Model'!$O32/('UW Model'!$O$15-'UW Model'!$O$14-1)+AA10,AA10) -> 0 | AC10: =IF(AND(AC$3>'UW Model'!$O$14+1,AC$3<='UW Model'!$O$15),'UW Model'!$O32/('UW Model'!$O$15-'UW Model'!$O$14-1)+AB10,AB10) -> 0 | AD10: =IF(AND(AD$3>'UW Model'!$O$14+1,AD$3<='UW Model'!$O$15),'UW Model'!$O32/('UW Model'!$O$15-'UW Model'!$O$14-1)+AC10,AC10) -> 0 | AE10: =IF(AND(AE$3>'UW Model'!$O$14+1,AE$3<='UW Model'!$O$15),'UW Model'!$O32/('UW Model'!$O$15-'UW Model'!$O$14-1)+AD10,AD10) -> 0 | AF10: =IF(AND(AF$3>'UW Model'!$O$14+1,AF$3<='UW Model'!$O$15),'UW Model'!$O32/('UW Model'!$O$15-'UW Model'!$O$14-1)+AE10,AE10) -> 0 | ... CE10: =IF(AND(CE$3>'UW Model'!$O$14+1,CE$3<='UW Model'!$O$15),'UW Model'!$O32/('UW Model'!$O$15-'UW Model'!$O$14-1)+CD10,CD10) -> 0
Q11: =IF('UW Model'!C33="","",'UW Model'!C33) | R11: =_xlfn.MAXIFS($X11:$CE11,$X$2:$CE$2,R$2) -> 0 | S11: =_xlfn.MAXIFS($X11:$CE11,$X$2:$CE$2,S$2) -> 0 | T11: =_xlfn.MAXIFS($X11:$CE11,$X$2:$CE$2,T$2) -> 0 | U11: =_xlfn.MAXIFS($X11:$CE11,$X$2:$CE$2,U$2) -> 0 | V11: =_xlfn.MAXIFS($X11:$CE11,$X$2:$CE$2,V$2) -> 0 | W11: 0 | X11: =IF(AND(X$3>'UW Model'!$O$14+1,X$3<='UW Model'!$O$15),'UW Model'!$O33/('UW Model'!$O$15-'UW Model'!$O$14-1)+W11,0) -> 0 | Y11: =IF(AND(Y$3>'UW Model'!$O$14+1,Y$3<='UW Model'!$O$15),'UW Model'!$O33/('UW Model'!$O$15-'UW Model'!$O$14-1)+X11,X11) -> 0 | Z11: =IF(AND(Z$3>'UW Model'!$O$14+1,Z$3<='UW Model'!$O$15),'UW Model'!$O33/('UW Model'!$O$15-'UW Model'!$O$14-1)+Y11,Y11) -> 0 | AA11: =IF(AND(AA$3>'UW Model'!$O$14+1,AA$3<='UW Model'!$O$15),'UW Model'!$O33/('UW Model'!$O$15-'UW Model'!$O$14-1)+Z11,Z11) -> 0 | AB11: =IF(AND(AB$3>'UW Model'!$O$14+1,AB$3<='UW Model'!$O$15),'UW Model'!$O33/('UW Model'!$O$15-'UW Model'!$O$14-1)+AA11,AA11) -> 0 | AC11: =IF(AND(AC$3>'UW Model'!$O$14+1,AC$3<='UW Model'!$O$15),'UW Model'!$O33/('UW Model'!$O$15-'UW Model'!$O$14-1)+AB11,AB11) -> 0 | AD11: =IF(AND(AD$3>'UW Model'!$O$14+1,AD$3<='UW Model'!$O$15),'UW Model'!$O33/('UW Model'!$O$15-'UW Model'!$O$14-1)+AC11,AC11) -> 0 | AE11: =IF(AND(AE$3>'UW Model'!$O$14+1,AE$3<='UW Model'!$O$15),'UW Model'!$O33/('UW Model'!$O$15-'UW Model'!$O$14-1)+AD11,AD11) -> 0 | AF11: =IF(AND(AF$3>'UW Model'!$O$14+1,AF$3<='UW Model'!$O$15),'UW Model'!$O33/('UW Model'!$O$15-'UW Model'!$O$14-1)+AE11,AE11) -> 0 | ... CE11: =IF(AND(CE$3>'UW Model'!$O$14+1,CE$3<='UW Model'!$O$15),'UW Model'!$O33/('UW Model'!$O$15-'UW Model'!$O$14-1)+CD11,CD11) -> 0
Q12: =IF('UW Model'!C34="","",'UW Model'!C34) | R12: =_xlfn.MAXIFS($X12:$CE12,$X$2:$CE$2,R$2) -> 0 | S12: =_xlfn.MAXIFS($X12:$CE12,$X$2:$CE$2,S$2) -> 0 | T12: =_xlfn.MAXIFS($X12:$CE12,$X$2:$CE$2,T$2) -> 0 | U12: =_xlfn.MAXIFS($X12:$CE12,$X$2:$CE$2,U$2) -> 0 | V12: =_xlfn.MAXIFS($X12:$CE12,$X$2:$CE$2,V$2) -> 0 | W12: 0 | X12: =IF(AND(X$3>'UW Model'!$O$14+1,X$3<='UW Model'!$O$15),'UW Model'!$O34/('UW Model'!$O$15-'UW Model'!$O$14-1)+W12,0) -> 0 | Y12: =IF(AND(Y$3>'UW Model'!$O$14+1,Y$3<='UW Model'!$O$15),'UW Model'!$O34/('UW Model'!$O$15-'UW Model'!$O$14-1)+X12,X12) -> 0 | Z12: =IF(AND(Z$3>'UW Model'!$O$14+1,Z$3<='UW Model'!$O$15),'UW Model'!$O34/('UW Model'!$O$15-'UW Model'!$O$14-1)+Y12,Y12) -> 0 | AA12: =IF(AND(AA$3>'UW Model'!$O$14+1,AA$3<='UW Model'!$O$15),'UW Model'!$O34/('UW Model'!$O$15-'UW Model'!$O$14-1)+Z12,Z12) -> 0 | AB12: =IF(AND(AB$3>'UW Model'!$O$14+1,AB$3<='UW Model'!$O$15),'UW Model'!$O34/('UW Model'!$O$15-'UW Model'!$O$14-1)+AA12,AA12) -> 0 | AC12: =IF(AND(AC$3>'UW Model'!$O$14+1,AC$3<='UW Model'!$O$15),'UW Model'!$O34/('UW Model'!$O$15-'UW Model'!$O$14-1)+AB12,AB12) -> 0 | AD12: =IF(AND(AD$3>'UW Model'!$O$14+1,AD$3<='UW Model'!$O$15),'UW Model'!$O34/('UW Model'!$O$15-'UW Model'!$O$14-1)+AC12,AC12) -> 0 | AE12: =IF(AND(AE$3>'UW Model'!$O$14+1,AE$3<='UW Model'!$O$15),'UW Model'!$O34/('UW Model'!$O$15-'UW Model'!$O$14-1)+AD12,AD12) -> 0 | AF12: =IF(AND(AF$3>'UW Model'!$O$14+1,AF$3<='UW Model'!$O$15),'UW Model'!$O34/('UW Model'!$O$15-'UW Model'!$O$14-1)+AE12,AE12) -> 0 | ... CE12: =IF(AND(CE$3>'UW Model'!$O$14+1,CE$3<='UW Model'!$O$15),'UW Model'!$O34/('UW Model'!$O$15-'UW Model'!$O$14-1)+CD12,CD12) -> 0
Q13: =IF('UW Model'!C35="","",'UW Model'!C35) | R13: =_xlfn.MAXIFS($X13:$CE13,$X$2:$CE$2,R$2) -> 0 | S13: =_xlfn.MAXIFS($X13:$CE13,$X$2:$CE$2,S$2) -> 0 | T13: =_xlfn.MAXIFS($X13:$CE13,$X$2:$CE$2,T$2) -> 0 | U13: =_xlfn.MAXIFS($X13:$CE13,$X$2:$CE$2,U$2) -> 0 | V13: =_xlfn.MAXIFS($X13:$CE13,$X$2:$CE$2,V$2) -> 0 | W13: 0 | X13: =IF(AND(X$3>'UW Model'!$O$14+1,X$3<='UW Model'!$O$15),'UW Model'!$O35/('UW Model'!$O$15-'UW Model'!$O$14-1)+W13,0) -> 0 | Y13: =IF(AND(Y$3>'UW Model'!$O$14+1,Y$3<='UW Model'!$O$15),'UW Model'!$O35/('UW Model'!$O$15-'UW Model'!$O$14-1)+X13,X13) -> 0 | Z13: =IF(AND(Z$3>'UW Model'!$O$14+1,Z$3<='UW Model'!$O$15),'UW Model'!$O35/('UW Model'!$O$15-'UW Model'!$O$14-1)+Y13,Y13) -> 0 | AA13: =IF(AND(AA$3>'UW Model'!$O$14+1,AA$3<='UW Model'!$O$15),'UW Model'!$O35/('UW Model'!$O$15-'UW Model'!$O$14-1)+Z13,Z13) -> 0 | AB13: =IF(AND(AB$3>'UW Model'!$O$14+1,AB$3<='UW Model'!$O$15),'UW Model'!$O35/('UW Model'!$O$15-'UW Model'!$O$14-1)+AA13,AA13) -> 0 | AC13: =IF(AND(AC$3>'UW Model'!$O$14+1,AC$3<='UW Model'!$O$15),'UW Model'!$O35/('UW Model'!$O$15-'UW Model'!$O$14-1)+AB13,AB13) -> 0 | AD13: =IF(AND(AD$3>'UW Model'!$O$14+1,AD$3<='UW Model'!$O$15),'UW Model'!$O35/('UW Model'!$O$15-'UW Model'!$O$14-1)+AC13,AC13) -> 0 | AE13: =IF(AND(AE$3>'UW Model'!$O$14+1,AE$3<='UW Model'!$O$15),'UW Model'!$O35/('UW Model'!$O$15-'UW Model'!$O$14-1)+AD13,AD13) -> 0 | AF13: =IF(AND(AF$3>'UW Model'!$O$14+1,AF$3<='UW Model'!$O$15),'UW Model'!$O35/('UW Model'!$O$15-'UW Model'!$O$14-1)+AE13,AE13) -> 0 | ... CE13: =IF(AND(CE$3>'UW Model'!$O$14+1,CE$3<='UW Model'!$O$15),'UW Model'!$O35/('UW Model'!$O$15-'UW Model'!$O$14-1)+CD13,CD13) -> 0
Q14: =IF('UW Model'!C36="","",'UW Model'!C36) | R14: =_xlfn.MAXIFS($X14:$CE14,$X$2:$CE$2,R$2) -> 0 | S14: =_xlfn.MAXIFS($X14:$CE14,$X$2:$CE$2,S$2) -> 0 | T14: =_xlfn.MAXIFS($X14:$CE14,$X$2:$CE$2,T$2) -> 0 | U14: =_xlfn.MAXIFS($X14:$CE14,$X$2:$CE$2,U$2) -> 0 | V14: =_xlfn.MAXIFS($X14:$CE14,$X$2:$CE$2,V$2) -> 0 | W14: 0 | X14: =IF(AND(X$3>'UW Model'!$O$14+1,X$3<='UW Model'!$O$15),'UW Model'!$O36/('UW Model'!$O$15-'UW Model'!$O$14-1)+W14,0) -> 0 | Y14: =IF(AND(Y$3>'UW Model'!$O$14+1,Y$3<='UW Model'!$O$15),'UW Model'!$O36/('UW Model'!$O$15-'UW Model'!$O$14-1)+X14,X14) -> 0 | Z14: =IF(AND(Z$3>'UW Model'!$O$14+1,Z$3<='UW Model'!$O$15),'UW Model'!$O36/('UW Model'!$O$15-'UW Model'!$O$14-1)+Y14,Y14) -> 0 | AA14: =IF(AND(AA$3>'UW Model'!$O$14+1,AA$3<='UW Model'!$O$15),'UW Model'!$O36/('UW Model'!$O$15-'UW Model'!$O$14-1)+Z14,Z14) -> 0 | AB14: =IF(AND(AB$3>'UW Model'!$O$14+1,AB$3<='UW Model'!$O$15),'UW Model'!$O36/('UW Model'!$O$15-'UW Model'!$O$14-1)+AA14,AA14) -> 0 | AC14: =IF(AND(AC$3>'UW Model'!$O$14+1,AC$3<='UW Model'!$O$15),'UW Model'!$O36/('UW Model'!$O$15-'UW Model'!$O$14-1)+AB14,AB14) -> 0 | AD14: =IF(AND(AD$3>'UW Model'!$O$14+1,AD$3<='UW Model'!$O$15),'UW Model'!$O36/('UW Model'!$O$15-'UW Model'!$O$14-1)+AC14,AC14) -> 0 | AE14: =IF(AND(AE$3>'UW Model'!$O$14+1,AE$3<='UW Model'!$O$15),'UW Model'!$O36/('UW Model'!$O$15-'UW Model'!$O$14-1)+AD14,AD14) -> 0 | AF14: =IF(AND(AF$3>'UW Model'!$O$14+1,AF$3<='UW Model'!$O$15),'UW Model'!$O36/('UW Model'!$O$15-'UW Model'!$O$14-1)+AE14,AE14) -> 0 | ... CE14: =IF(AND(CE$3>'UW Model'!$O$14+1,CE$3<='UW Model'!$O$15),'UW Model'!$O36/('UW Model'!$O$15-'UW Model'!$O$14-1)+CD14,CD14) -> 0
Q15: =IF('UW Model'!C37="","",'UW Model'!C37) | R15: =_xlfn.MAXIFS($X15:$CE15,$X$2:$CE$2,R$2) -> 0 | S15: =_xlfn.MAXIFS($X15:$CE15,$X$2:$CE$2,S$2) -> 0 | T15: =_xlfn.MAXIFS($X15:$CE15,$X$2:$CE$2,T$2) -> 0 | U15: =_xlfn.MAXIFS($X15:$CE15,$X$2:$CE$2,U$2) -> 0 | V15: =_xlfn.MAXIFS($X15:$CE15,$X$2:$CE$2,V$2) -> 0 | W15: 0 | X15: =IF(AND(X$3>'UW Model'!$O$14+1,X$3<='UW Model'!$O$15),'UW Model'!$O37/('UW Model'!$O$15-'UW Model'!$O$14-1)+W15,0) -> 0 | Y15: =IF(AND(Y$3>'UW Model'!$O$14+1,Y$3<='UW Model'!$O$15),'UW Model'!$O37/('UW Model'!$O$15-'UW Model'!$O$14-1)+X15,X15) -> 0 | Z15: =IF(AND(Z$3>'UW Model'!$O$14+1,Z$3<='UW Model'!$O$15),'UW Model'!$O37/('UW Model'!$O$15-'UW Model'!$O$14-1)+Y15,Y15) -> 0 | AA15: =IF(AND(AA$3>'UW Model'!$O$14+1,AA$3<='UW Model'!$O$15),'UW Model'!$O37/('UW Model'!$O$15-'UW Model'!$O$14-1)+Z15,Z15) -> 0 | AB15: =IF(AND(AB$3>'UW Model'!$O$14+1,AB$3<='UW Model'!$O$15),'UW Model'!$O37/('UW Model'!$O$15-'UW Model'!$O$14-1)+AA15,AA15) -> 0 | AC15: =IF(AND(AC$3>'UW Model'!$O$14+1,AC$3<='UW Model'!$O$15),'UW Model'!$O37/('UW Model'!$O$15-'UW Model'!$O$14-1)+AB15,AB15) -> 0 | AD15: =IF(AND(AD$3>'UW Model'!$O$14+1,AD$3<='UW Model'!$O$15),'UW Model'!$O37/('UW Model'!$O$15-'UW Model'!$O$14-1)+AC15,AC15) -> 0 | AE15: =IF(AND(AE$3>'UW Model'!$O$14+1,AE$3<='UW Model'!$O$15),'UW Model'!$O37/('UW Model'!$O$15-'UW Model'!$O$14-1)+AD15,AD15) -> 0 | AF15: =IF(AND(AF$3>'UW Model'!$O$14+1,AF$3<='UW Model'!$O$15),'UW Model'!$O37/('UW Model'!$O$15-'UW Model'!$O$14-1)+AE15,AE15) -> 0 | ... CE15: =IF(AND(CE$3>'UW Model'!$O$14+1,CE$3<='UW Model'!$O$15),'UW Model'!$O37/('UW Model'!$O$15-'UW Model'!$O$14-1)+CD15,CD15) -> 0
Q16: =IF('UW Model'!C38="","",'UW Model'!C38) | R16: =_xlfn.MAXIFS($X16:$CE16,$X$2:$CE$2,R$2) -> 0 | S16: =_xlfn.MAXIFS($X16:$CE16,$X$2:$CE$2,S$2) -> 0 | T16: =_xlfn.MAXIFS($X16:$CE16,$X$2:$CE$2,T$2) -> 0 | U16: =_xlfn.MAXIFS($X16:$CE16,$X$2:$CE$2,U$2) -> 0 | V16: =_xlfn.MAXIFS($X16:$CE16,$X$2:$CE$2,V$2) -> 0 | W16: 0 | X16: =IF(AND(X$3>'UW Model'!$O$14+1,X$3<='UW Model'!$O$15),'UW Model'!$O38/('UW Model'!$O$15-'UW Model'!$O$14-1)+W16,0) -> 0 | Y16: =IF(AND(Y$3>'UW Model'!$O$14+1,Y$3<='UW Model'!$O$15),'UW Model'!$O38/('UW Model'!$O$15-'UW Model'!$O$14-1)+X16,X16) -> 0 | Z16: =IF(AND(Z$3>'UW Model'!$O$14+1,Z$3<='UW Model'!$O$15),'UW Model'!$O38/('UW Model'!$O$15-'UW Model'!$O$14-1)+Y16,Y16) -> 0 | AA16: =IF(AND(AA$3>'UW Model'!$O$14+1,AA$3<='UW Model'!$O$15),'UW Model'!$O38/('UW Model'!$O$15-'UW Model'!$O$14-1)+Z16,Z16) -> 0 | AB16: =IF(AND(AB$3>'UW Model'!$O$14+1,AB$3<='UW Model'!$O$15),'UW Model'!$O38/('UW Model'!$O$15-'UW Model'!$O$14-1)+AA16,AA16) -> 0 | AC16: =IF(AND(AC$3>'UW Model'!$O$14+1,AC$3<='UW Model'!$O$15),'UW Model'!$O38/('UW Model'!$O$15-'UW Model'!$O$14-1)+AB16,AB16) -> 0 | AD16: =IF(AND(AD$3>'UW Model'!$O$14+1,AD$3<='UW Model'!$O$15),'UW Model'!$O38/('UW Model'!$O$15-'UW Model'!$O$14-1)+AC16,AC16) -> 0 | AE16: =IF(AND(AE$3>'UW Model'!$O$14+1,AE$3<='UW Model'!$O$15),'UW Model'!$O38/('UW Model'!$O$15-'UW Model'!$O$14-1)+AD16,AD16) -> 0 | AF16: =IF(AND(AF$3>'UW Model'!$O$14+1,AF$3<='UW Model'!$O$15),'UW Model'!$O38/('UW Model'!$O$15-'UW Model'!$O$14-1)+AE16,AE16) -> 0 | ... CE16: =IF(AND(CE$3>'UW Model'!$O$14+1,CE$3<='UW Model'!$O$15),'UW Model'!$O38/('UW Model'!$O$15-'UW Model'!$O$14-1)+CD16,CD16) -> 0
Q17: =IF('UW Model'!C39="","",'UW Model'!C39) | R17: =_xlfn.MAXIFS($X17:$CE17,$X$2:$CE$2,R$2) -> 0 | S17: =_xlfn.MAXIFS($X17:$CE17,$X$2:$CE$2,S$2) -> 0 | T17: =_xlfn.MAXIFS($X17:$CE17,$X$2:$CE$2,T$2) -> 0 | U17: =_xlfn.MAXIFS($X17:$CE17,$X$2:$CE$2,U$2) -> 0 | V17: =_xlfn.MAXIFS($X17:$CE17,$X$2:$CE$2,V$2) -> 0 | W17: 0 | X17: =IF(AND(X$3>'UW Model'!$O$14+1,X$3<='UW Model'!$O$15),'UW Model'!$O39/('UW Model'!$O$15-'UW Model'!$O$14-1)+W17,0) -> 0 | Y17: =IF(AND(Y$3>'UW Model'!$O$14+1,Y$3<='UW Model'!$O$15),'UW Model'!$O39/('UW Model'!$O$15-'UW Model'!$O$14-1)+X17,X17) -> 0 | Z17: =IF(AND(Z$3>'UW Model'!$O$14+1,Z$3<='UW Model'!$O$15),'UW Model'!$O39/('UW Model'!$O$15-'UW Model'!$O$14-1)+Y17,Y17) -> 0 | AA17: =IF(AND(AA$3>'UW Model'!$O$14+1,AA$3<='UW Model'!$O$15),'UW Model'!$O39/('UW Model'!$O$15-'UW Model'!$O$14-1)+Z17,Z17) -> 0 | AB17: =IF(AND(AB$3>'UW Model'!$O$14+1,AB$3<='UW Model'!$O$15),'UW Model'!$O39/('UW Model'!$O$15-'UW Model'!$O$14-1)+AA17,AA17) -> 0 | AC17: =IF(AND(AC$3>'UW Model'!$O$14+1,AC$3<='UW Model'!$O$15),'UW Model'!$O39/('UW Model'!$O$15-'UW Model'!$O$14-1)+AB17,AB17) -> 0 | AD17: =IF(AND(AD$3>'UW Model'!$O$14+1,AD$3<='UW Model'!$O$15),'UW Model'!$O39/('UW Model'!$O$15-'UW Model'!$O$14-1)+AC17,AC17) -> 0 | AE17: =IF(AND(AE$3>'UW Model'!$O$14+1,AE$3<='UW Model'!$O$15),'UW Model'!$O39/('UW Model'!$O$15-'UW Model'!$O$14-1)+AD17,AD17) -> 0 | AF17: =IF(AND(AF$3>'UW Model'!$O$14+1,AF$3<='UW Model'!$O$15),'UW Model'!$O39/('UW Model'!$O$15-'UW Model'!$O$14-1)+AE17,AE17) -> 0 | ... CE17: =IF(AND(CE$3>'UW Model'!$O$14+1,CE$3<='UW Model'!$O$15),'UW Model'!$O39/('UW Model'!$O$15-'UW Model'!$O$14-1)+CD17,CD17) -> 0
... Q20: =IF('UW Model'!C42="","",'UW Model'!C42) | R20: =_xlfn.MAXIFS($X20:$CE20,$X$2:$CE$2,R$2) -> 0 | S20: =_xlfn.MAXIFS($X20:$CE20,$X$2:$CE$2,S$2) -> 0 | T20: =_xlfn.MAXIFS($X20:$CE20,$X$2:$CE$2,T$2) -> 0 | U20: =_xlfn.MAXIFS($X20:$CE20,$X$2:$CE$2,U$2) -> 0 | V20: =_xlfn.MAXIFS($X20:$CE20,$X$2:$CE$2,V$2) -> 0 | W20: 0 | X20: =IF(AND(X$3>'UW Model'!$O$14+1,X$3<='UW Model'!$O$15),'UW Model'!$O42/('UW Model'!$O$15-'UW Model'!$O$14-1)+W20,0) -> 0 | Y20: =IF(AND(Y$3>'UW Model'!$O$14+1,Y$3<='UW Model'!$O$15),'UW Model'!$O42/('UW Model'!$O$15-'UW Model'!$O$14-1)+X20,X20) -> 0 | Z20: =IF(AND(Z$3>'UW Model'!$O$14+1,Z$3<='UW Model'!$O$15),'UW Model'!$O42/('UW Model'!$O$15-'UW Model'!$O$14-1)+Y20,Y20) -> 0 | AA20: =IF(AND(AA$3>'UW Model'!$O$14+1,AA$3<='UW Model'!$O$15),'UW Model'!$O42/('UW Model'!$O$15-'UW Model'!$O$14-1)+Z20,Z20) -> 0 | AB20: =IF(AND(AB$3>'UW Model'!$O$14+1,AB$3<='UW Model'!$O$15),'UW Model'!$O42/('UW Model'!$O$15-'UW Model'!$O$14-1)+AA20,AA20) -> 0 | AC20: =IF(AND(AC$3>'UW Model'!$O$14+1,AC$3<='UW Model'!$O$15),'UW Model'!$O42/('UW Model'!$O$15-'UW Model'!$O$14-1)+AB20,AB20) -> 0 | AD20: =IF(AND(AD$3>'UW Model'!$O$14+1,AD$3<='UW Model'!$O$15),'UW Model'!$O42/('UW Model'!$O$15-'UW Model'!$O$14-1)+AC20,AC20) -> 0 | AE20: =IF(AND(AE$3>'UW Model'!$O$14+1,AE$3<='UW Model'!$O$15),'UW Model'!$O42/('UW Model'!$O$15-'UW Model'!$O$14-1)+AD20,AD20) -> 0 | AF20: =IF(AND(AF$3>'UW Model'!$O$14+1,AF$3<='UW Model'!$O$15),'UW Model'!$O42/('UW Model'!$O$15-'UW Model'!$O$14-1)+AE20,AE20) -> 0 | ... CE20: =IF(AND(CE$3>'UW Model'!$O$14+1,CE$3<='UW Model'!$O$15),'UW Model'!$O42/('UW Model'!$O$15-'UW Model'!$O$14-1)+CD20,CD20) -> 0
Q21: Reno GPR Total | R21: =SUM(R22:R36) -> 0 | S21: =SUM(S22:S36) -> 0 | T21: =SUM(T22:T36) -> 0 | U21: =SUM(U22:U36) -> 0 | V21: =SUM(V22:V36) -> 0 | W21: =SUM(W22:W36) -> 0 | X21: =SUM(X22:X36) -> 0 | Y21: =SUM(Y22:Y36) -> 0 | ... CE21: =SUM(CE22:CE36) -> 0
Q22: =$Q$6 | R22: =SUMIF($X$2:$CE$2,R$2,$X22:$CE22) -> 0 | S22: =SUMIF($X$2:$CE$2,S$2,$X22:$CE22) -> 0 | T22: =SUMIF($X$2:$CE$2,T$2,$X22:$CE22) -> 0 | U22: =SUMIF($X$2:$CE$2,U$2,$X22:$CE22) -> 0 | V22: =SUMIF($X$2:$CE$2,V$2,$X22:$CE22) -> 0 | W22: 0 | X22: =X6*X38 -> 0 | Y22: =Y6*Y38 -> 0 | Z22: =Z6*Z38 -> 0 | AA22: =AA6*AA38 -> 0 | AB22: =AB6*AB38 -> 0 | AC22: =AC6*AC38 -> 0 | AD22: =AD6*AD38 -> 0 | AE22: =AE6*AE38 -> 0 | ... CE22: =CE6*CE38 -> 0
Q23: =$Q$7 | R23: =SUMIF($X$2:$CE$2,R$2,$X23:$CE23) -> 0 | S23: =SUMIF($X$2:$CE$2,S$2,$X23:$CE23) -> 0 | T23: =SUMIF($X$2:$CE$2,T$2,$X23:$CE23) -> 0 | U23: =SUMIF($X$2:$CE$2,U$2,$X23:$CE23) -> 0 | V23: =SUMIF($X$2:$CE$2,V$2,$X23:$CE23) -> 0 | W23: 0 | X23: =X7*X39 -> 0 | Y23: =Y7*Y39 -> 0 | Z23: =Z7*Z39 -> 0 | AA23: =AA7*AA39 -> 0 | AB23: =AB7*AB39 -> 0 | AC23: =AC7*AC39 -> 0 | AD23: =AD7*AD39 -> 0 | AE23: =AE7*AE39 -> 0 | ... CE23: =CE7*CE39 -> 0
Q24: =$Q$8 | R24: =SUMIF($X$2:$CE$2,R$2,$X24:$CE24) -> 0 | S24: =SUMIF($X$2:$CE$2,S$2,$X24:$CE24) -> 0 | T24: =SUMIF($X$2:$CE$2,T$2,$X24:$CE24) -> 0 | U24: =SUMIF($X$2:$CE$2,U$2,$X24:$CE24) -> 0 | V24: =SUMIF($X$2:$CE$2,V$2,$X24:$CE24) -> 0 | W24: 0 | X24: =X8*X40 -> 0 | Y24: =Y8*Y40 -> 0 | Z24: =Z8*Z40 -> 0 | AA24: =AA8*AA40 -> 0 | AB24: =AB8*AB40 -> 0 | AC24: =AC8*AC40 -> 0 | AD24: =AD8*AD40 -> 0 | AE24: =AE8*AE40 -> 0 | ... CE24: =CE8*CE40 -> 0
Q25: =$Q$9 | R25: =SUMIF($X$2:$CE$2,R$2,$X25:$CE25) -> 0 | S25: =SUMIF($X$2:$CE$2,S$2,$X25:$CE25) -> 0 | T25: =SUMIF($X$2:$CE$2,T$2,$X25:$CE25) -> 0 | U25: =SUMIF($X$2:$CE$2,U$2,$X25:$CE25) -> 0 | V25: =SUMIF($X$2:$CE$2,V$2,$X25:$CE25) -> 0 | W25: 0 | X25: =X9*X41 -> 0 | Y25: =Y9*Y41 -> 0 | Z25: =Z9*Z41 -> 0 | AA25: =AA9*AA41 -> 0 | AB25: =AB9*AB41 -> 0 | AC25: =AC9*AC41 -> 0 | AD25: =AD9*AD41 -> 0 | AE25: =AE9*AE41 -> 0 | ... CE25: =CE9*CE41 -> 0
Q26: =$Q$10 | R26: =SUMIF($X$2:$CE$2,R$2,$X26:$CE26) -> 0 | S26: =SUMIF($X$2:$CE$2,S$2,$X26:$CE26) -> 0 | T26: =SUMIF($X$2:$CE$2,T$2,$X26:$CE26) -> 0 | U26: =SUMIF($X$2:$CE$2,U$2,$X26:$CE26) -> 0 | V26: =SUMIF($X$2:$CE$2,V$2,$X26:$CE26) -> 0 | W26: 0 | X26: =X10*X42 -> 0 | Y26: =Y10*Y42 -> 0 | Z26: =Z10*Z42 -> 0 | AA26: =AA10*AA42 -> 0 | AB26: =AB10*AB42 -> 0 | AC26: =AC10*AC42 -> 0 | AD26: =AD10*AD42 -> 0 | AE26: =AE10*AE42 -> 0 | ... CE26: =CE10*CE42 -> 0
Q27: =$Q$11 | R27: =SUMIF($X$2:$CE$2,R$2,$X27:$CE27) -> 0 | S27: =SUMIF($X$2:$CE$2,S$2,$X27:$CE27) -> 0 | T27: =SUMIF($X$2:$CE$2,T$2,$X27:$CE27) -> 0 | U27: =SUMIF($X$2:$CE$2,U$2,$X27:$CE27) -> 0 | V27: =SUMIF($X$2:$CE$2,V$2,$X27:$CE27) -> 0 | W27: 0 | X27: =X11*X43 -> 0 | Y27: =Y11*Y43 -> 0 | Z27: =Z11*Z43 -> 0 | AA27: =AA11*AA43 -> 0 | AB27: =AB11*AB43 -> 0 | AC27: =AC11*AC43 -> 0 | AD27: =AD11*AD43 -> 0 | AE27: =AE11*AE43 -> 0 | ... CE27: =CE11*CE43 -> 0
Q28: =$Q$12 | R28: =SUMIF($X$2:$CE$2,R$2,$X28:$CE28) -> 0 | S28: =SUMIF($X$2:$CE$2,S$2,$X28:$CE28) -> 0 | T28: =SUMIF($X$2:$CE$2,T$2,$X28:$CE28) -> 0 | U28: =SUMIF($X$2:$CE$2,U$2,$X28:$CE28) -> 0 | V28: =SUMIF($X$2:$CE$2,V$2,$X28:$CE28) -> 0 | W28: 0 | X28: =X12*X44 -> 0 | Y28: =Y12*Y44 -> 0 | Z28: =Z12*Z44 -> 0 | AA28: =AA12*AA44 -> 0 | AB28: =AB12*AB44 -> 0 | AC28: =AC12*AC44 -> 0 | AD28: =AD12*AD44 -> 0 | AE28: =AE12*AE44 -> 0 | ... CE28: =CE12*CE44 -> 0
Q29: =$Q$13 | R29: =SUMIF($X$2:$CE$2,R$2,$X29:$CE29) -> 0 | S29: =SUMIF($X$2:$CE$2,S$2,$X29:$CE29) -> 0 | T29: =SUMIF($X$2:$CE$2,T$2,$X29:$CE29) -> 0 | U29: =SUMIF($X$2:$CE$2,U$2,$X29:$CE29) -> 0 | V29: =SUMIF($X$2:$CE$2,V$2,$X29:$CE29) -> 0 | W29: 0 | X29: =X13*X45 -> 0 | Y29: =Y13*Y45 -> 0 | Z29: =Z13*Z45 -> 0 | AA29: =AA13*AA45 -> 0 | AB29: =AB13*AB45 -> 0 | AC29: =AC13*AC45 -> 0 | AD29: =AD13*AD45 -> 0 | AE29: =AE13*AE45 -> 0 | ... CE29: =CE13*CE45 -> 0
Q30: =$Q$14 | R30: =SUMIF($X$2:$CE$2,R$2,$X30:$CE30) -> 0 | S30: =SUMIF($X$2:$CE$2,S$2,$X30:$CE30) -> 0 | T30: =SUMIF($X$2:$CE$2,T$2,$X30:$CE30) -> 0 | U30: =SUMIF($X$2:$CE$2,U$2,$X30:$CE30) -> 0 | V30: =SUMIF($X$2:$CE$2,V$2,$X30:$CE30) -> 0 | W30: 0 | X30: =X14*X46 -> 0 | Y30: =Y14*Y46 -> 0 | Z30: =Z14*Z46 -> 0 | AA30: =AA14*AA46 -> 0 | AB30: =AB14*AB46 -> 0 | AC30: =AC14*AC46 -> 0 | AD30: =AD14*AD46 -> 0 | AE30: =AE14*AE46 -> 0 | ... CE30: =CE14*CE46 -> 0
Q31: =$Q$15 | R31: =SUMIF($X$2:$CE$2,R$2,$X31:$CE31) -> 0 | S31: =SUMIF($X$2:$CE$2,S$2,$X31:$CE31) -> 0 | T31: =SUMIF($X$2:$CE$2,T$2,$X31:$CE31) -> 0 | U31: =SUMIF($X$2:$CE$2,U$2,$X31:$CE31) -> 0 | V31: =SUMIF($X$2:$CE$2,V$2,$X31:$CE31) -> 0 | W31: 0 | X31: =X15*X47 -> 0 | Y31: =Y15*Y47 -> 0 | Z31: =Z15*Z47 -> 0 | AA31: =AA15*AA47 -> 0 | AB31: =AB15*AB47 -> 0 | AC31: =AC15*AC47 -> 0 | AD31: =AD15*AD47 -> 0 | AE31: =AE15*AE47 -> 0 | ... CE31: =CE15*CE47 -> 0
Q32: =$Q$16 | R32: =SUMIF($X$2:$CE$2,R$2,$X32:$CE32) -> 0 | S32: =SUMIF($X$2:$CE$2,S$2,$X32:$CE32) -> 0 | T32: =SUMIF($X$2:$CE$2,T$2,$X32:$CE32) -> 0 | U32: =SUMIF($X$2:$CE$2,U$2,$X32:$CE32) -> 0 | V32: =SUMIF($X$2:$CE$2,V$2,$X32:$CE32) -> 0 | W32: 0 | X32: =X16*X48 -> 0 | Y32: =Y16*Y48 -> 0 | Z32: =Z16*Z48 -> 0 | AA32: =AA16*AA48 -> 0 | AB32: =AB16*AB48 -> 0 | AC32: =AC16*AC48 -> 0 | AD32: =AD16*AD48 -> 0 | AE32: =AE16*AE48 -> 0 | ... CE32: =CE16*CE48 -> 0
Q33: =$Q$17 | R33: =SUMIF($X$2:$CE$2,R$2,$X33:$CE33) -> 0 | S33: =SUMIF($X$2:$CE$2,S$2,$X33:$CE33) -> 0 | T33: =SUMIF($X$2:$CE$2,T$2,$X33:$CE33) -> 0 | U33: =SUMIF($X$2:$CE$2,U$2,$X33:$CE33) -> 0 | V33: =SUMIF($X$2:$CE$2,V$2,$X33:$CE33) -> 0 | W33: 0 | X33: =X17*X49 -> 0 | Y33: =Y17*Y49 -> 0 | Z33: =Z17*Z49 -> 0 | AA33: =AA17*AA49 -> 0 | AB33: =AB17*AB49 -> 0 | AC33: =AC17*AC49 -> 0 | AD33: =AD17*AD49 -> 0 | AE33: =AE17*AE49 -> 0 | ... CE33: =CE17*CE49 -> 0
Q34: =$Q$18 | R34: =SUMIF($X$2:$CE$2,R$2,$X34:$CE34) -> 0 | S34: =SUMIF($X$2:$CE$2,S$2,$X34:$CE34) -> 0 | T34: =SUMIF($X$2:$CE$2,T$2,$X34:$CE34) -> 0 | U34: =SUMIF($X$2:$CE$2,U$2,$X34:$CE34) -> 0 | V34: =SUMIF($X$2:$CE$2,V$2,$X34:$CE34) -> 0 | W34: 0 | X34: =X18*X50 -> 0 | Y34: =Y18*Y50 -> 0 | Z34: =Z18*Z50 -> 0 | AA34: =AA18*AA50 -> 0 | AB34: =AB18*AB50 -> 0 | AC34: =AC18*AC50 -> 0 | AD34: =AD18*AD50 -> 0 | AE34: =AE18*AE50 -> 0 | ... CE34: =CE18*CE50 -> 0
Q35: =$Q$19 | R35: =SUMIF($X$2:$CE$2,R$2,$X35:$CE35) -> 0 | S35: =SUMIF($X$2:$CE$2,S$2,$X35:$CE35) -> 0 | T35: =SUMIF($X$2:$CE$2,T$2,$X35:$CE35) -> 0 | U35: =SUMIF($X$2:$CE$2,U$2,$X35:$CE35) -> 0 | V35: =SUMIF($X$2:$CE$2,V$2,$X35:$CE35) -> 0 | W35: 0 | X35: =X19*X51 -> 0 | Y35: =Y19*Y51 -> 0 | Z35: =Z19*Z51 -> 0 | AA35: =AA19*AA51 -> 0 | AB35: =AB19*AB51 -> 0 | AC35: =AC19*AC51 -> 0 | AD35: =AD19*AD51 -> 0 | AE35: =AE19*AE51 -> 0 | ... CE35: =CE19*CE51 -> 0
Q36: =$Q$20 | R36: =SUMIF($X$2:$CE$2,R$2,$X36:$CE36) -> 0 | S36: =SUMIF($X$2:$CE$2,S$2,$X36:$CE36) -> 0 | T36: =SUMIF($X$2:$CE$2,T$2,$X36:$CE36) -> 0 | U36: =SUMIF($X$2:$CE$2,U$2,$X36:$CE36) -> 0 | V36: =SUMIF($X$2:$CE$2,V$2,$X36:$CE36) -> 0 | W36: 0 | X36: =X20*X52 -> 0 | Y36: =Y20*Y52 -> 0 | Z36: =Z20*Z52 -> 0 | AA36: =AA20*AA52 -> 0 | AB36: =AB20*AB52 -> 0 | AC36: =AC20*AC52 -> 0 | AD36: =AD20*AD52 -> 0 | AE36: =AE20*AE52 -> 0 | ... CE36: =CE20*CE52 -> 0
Q37: Reno Rent Total | R37: =IFERROR(SUMIF($X$2:$CE$2,R$2,$X21:$CE21)/SUMIF($X$2:$CE$2,R$2,$X5:$CE5),0) -> 0 | S37: =IFERROR(SUMIF($X$2:$CE$2,S$2,$X21:$CE21)/SUMIF($X$2:$CE$2,S$2,$X5:$CE5),0) -> 0 | T37: =IFERROR(SUMIF($X$2:$CE$2,T$2,$X21:$CE21)/SUMIF($X$2:$CE$2,T$2,$X5:$CE5),0) -> 0 | U37: =IFERROR(SUMIF($X$2:$CE$2,U$2,$X21:$CE21)/SUMIF($X$2:$CE$2,U$2,$X5:$CE5),0) -> 0 | V37: =IFERROR(SUMIF($X$2:$CE$2,V$2,$X21:$CE21)/SUMIF($X$2:$CE$2,V$2,$X5:$CE5),0) -> 0 | W37: =IFERROR(W21/W5,0) -> 0 | X37: =IFERROR(X21/X5,0) -> 0 | Y37: =IFERROR(Y21/Y5,0) -> 0 | Z37: =IFERROR(Z21/Z5,0) -> 0 | AA37: =IFERROR(AA21/AA5,0) -> 0 | AB37: =IFERROR(AB21/AB5,0) -> 0 | AC37: =IFERROR(AC21/AC5,0) -> 0 | AD37: =IFERROR(AD21/AD5,0) -> 0 | ... CE37: =IFERROR(CE21/CE5,0) -> 0
Q38: =$Q$6 | R38: =IFERROR(SUMIF($X$2:$CE$2,R$2,$X22:$CE22)/SUMIF($X$2:$CE$2,R$2,$X6:$CE6),0) -> 0 | S38: =IFERROR(SUMIF($X$2:$CE$2,S$2,$X22:$CE22)/SUMIF($X$2:$CE$2,S$2,$X6:$CE6),0) -> 0 | T38: =IFERROR(SUMIF($X$2:$CE$2,T$2,$X22:$CE22)/SUMIF($X$2:$CE$2,T$2,$X6:$CE6),0) -> 0 | U38: =IFERROR(SUMIF($X$2:$CE$2,U$2,$X22:$CE22)/SUMIF($X$2:$CE$2,U$2,$X6:$CE6),0) -> 0 | V38: =IFERROR(SUMIF($X$2:$CE$2,V$2,$X22:$CE22)/SUMIF($X$2:$CE$2,V$2,$X6:$CE6),0) -> 0 | W38: =IF(SUM(R6:V6)>0,'UW Model'!T28,0) -> 0 | X38: =HLOOKUP((X$2-1)*12,$W$3:$CE$52,ROW()-2,0)*(1+(HLOOKUP(X$2,'UW Model'!$M$103:$Q$104,2,0)/12)*(X$3-((X$2-1)*12))) -> 0 | Y38: =HLOOKUP((Y$2-1)*12,$W$3:$CE$52,ROW()-2,0)*(1+(HLOOKUP(Y$2,'UW Model'!$M$103:$Q$104,2,0)/12)*(Y$3-((Y$2-1)*12))) -> 0 | Z38: =HLOOKUP((Z$2-1)*12,$W$3:$CE$52,ROW()-2,0)*(1+(HLOOKUP(Z$2,'UW Model'!$M$103:$Q$104,2,0)/12)*(Z$3-((Z$2-1)*12))) -> 0 | AA38: =HLOOKUP((AA$2-1)*12,$W$3:$CE$52,ROW()-2,0)*(1+(HLOOKUP(AA$2,'UW Model'!$M$103:$Q$104,2,0)/12)*(AA$3-((AA$2-1)*12))) -> 0 | AB38: =HLOOKUP((AB$2-1)*12,$W$3:$CE$52,ROW()-2,0)*(1+(HLOOKUP(AB$2,'UW Model'!$M$103:$Q$104,2,0)/12)*(AB$3-((AB$2-1)*12))) -> 0 | AC38: =HLOOKUP((AC$2-1)*12,$W$3:$CE$52,ROW()-2,0)*(1+(HLOOKUP(AC$2,'UW Model'!$M$103:$Q$104,2,0)/12)*(AC$3-((AC$2-1)*12))) -> 0 | AD38: =HLOOKUP((AD$2-1)*12,$W$3:$CE$52,ROW()-2,0)*(1+(HLOOKUP(AD$2,'UW Model'!$M$103:$Q$104,2,0)/12)*(AD$3-((AD$2-1)*12))) -> 0 | AE38: =HLOOKUP((AE$2-1)*12,$W$3:$CE$52,ROW()-2,0)*(1+(HLOOKUP(AE$2,'UW Model'!$M$103:$Q$104,2,0)/12)*(AE$3-((AE$2-1)*12))) -> 0 | ... CE38: =HLOOKUP((CE$2-1)*12,$W$3:$CE$52,ROW()-2,0)*(1+(HLOOKUP(CE$2,'UW Model'!$M$103:$Q$104,2,0)/12)*(CE$3-((CE$2-1)*12))) -> 0
Q39: =$Q$7 | R39: =IFERROR(SUMIF($X$2:$CE$2,R$2,$X23:$CE23)/SUMIF($X$2:$CE$2,R$2,$X7:$CE7),0) -> 0 | S39: =IFERROR(SUMIF($X$2:$CE$2,S$2,$X23:$CE23)/SUMIF($X$2:$CE$2,S$2,$X7:$CE7),0) -> 0 | T39: =IFERROR(SUMIF($X$2:$CE$2,T$2,$X23:$CE23)/SUMIF($X$2:$CE$2,T$2,$X7:$CE7),0) -> 0 | U39: =IFERROR(SUMIF($X$2:$CE$2,U$2,$X23:$CE23)/SUMIF($X$2:$CE$2,U$2,$X7:$CE7),0) -> 0 | V39: =IFERROR(SUMIF($X$2:$CE$2,V$2,$X23:$CE23)/SUMIF($X$2:$CE$2,V$2,$X7:$CE7),0) -> 0 | W39: =IF(SUM(R7:V7)>0,'UW Model'!T29,0) -> 0 | X39: =HLOOKUP((X$2-1)*12,$W$3:$CE$52,ROW()-2,0)*(1+(HLOOKUP(X$2,'UW Model'!$M$103:$Q$104,2,0)/12)*(X$3-((X$2-1)*12))) -> 0 | Y39: =HLOOKUP((Y$2-1)*12,$W$3:$CE$52,ROW()-2,0)*(1+(HLOOKUP(Y$2,'UW Model'!$M$103:$Q$104,2,0)/12)*(Y$3-((Y$2-1)*12))) -> 0 | Z39: =HLOOKUP((Z$2-1)*12,$W$3:$CE$52,ROW()-2,0)*(1+(HLOOKUP(Z$2,'UW Model'!$M$103:$Q$104,2,0)/12)*(Z$3-((Z$2-1)*12))) -> 0 | AA39: =HLOOKUP((AA$2-1)*12,$W$3:$CE$52,ROW()-2,0)*(1+(HLOOKUP(AA$2,'UW Model'!$M$103:$Q$104,2,0)/12)*(AA$3-((AA$2-1)*12))) -> 0 | AB39: =HLOOKUP((AB$2-1)*12,$W$3:$CE$52,ROW()-2,0)*(1+(HLOOKUP(AB$2,'UW Model'!$M$103:$Q$104,2,0)/12)*(AB$3-((AB$2-1)*12))) -> 0 | AC39: =HLOOKUP((AC$2-1)*12,$W$3:$CE$52,ROW()-2,0)*(1+(HLOOKUP(AC$2,'UW Model'!$M$103:$Q$104,2,0)/12)*(AC$3-((AC$2-1)*12))) -> 0 | AD39: =HLOOKUP((AD$2-1)*12,$W$3:$CE$52,ROW()-2,0)*(1+(HLOOKUP(AD$2,'UW Model'!$M$103:$Q$104,2,0)/12)*(AD$3-((AD$2-1)*12))) -> 0 | AE39: =HLOOKUP((AE$2-1)*12,$W$3:$CE$52,ROW()-2,0)*(1+(HLOOKUP(AE$2,'UW Model'!$M$103:$Q$104,2,0)/12)*(AE$3-((AE$2-1)*12))) -> 0 | ... CE39: =HLOOKUP((CE$2-1)*12,$W$3:$CE$52,ROW()-2,0)*(1+(HLOOKUP(CE$2,'UW Model'!$M$103:$Q$104,2,0)/12)*(CE$3-((CE$2-1)*12))) -> 0
